Workbook
Name \p: #REF!
Name ___Ibr1: #REF!
Name ___lmb1: #REF!
Name __asb5: [1]BAHAN!$E$78
Name __BAB2: #REF!
Name __BAB3: '[2]met bab3'!#REF!
Name __BAB7: #REF!
Name __BAB8: '[2]anal bab8'!#REF!
Name __cor175: #REF!
Name __cor225: #REF!
Name __cor300: #REF!
Name __EEE01: #REF!
Name __EEE02: #REF!
Name __EEE03: #REF!
Name __EEE04: #REF!
Name __EEE05: #REF!
Name __EEE06: #REF!
Name __EEE07: #REF!
Name __EEE08: #REF!
Name __EEE09: #REF!
Name __EEE10: #REF!
Name __EEE11: #REF!
Name __EEE12: #REF!
Name __EEE13: #REF!
Name __EEE14: #REF!
Name __EEE15: #REF!
Name __EEE16: #REF!
Name __EEE17: #REF!
Name __EEE18: #REF!
Name __EEE19: #REF!
Name __EEE20: #REF!
Name __EEE21: #REF!
Name __EEE22: #REF!
Name __EEE23: #REF!
Name __EEE24: #REF!
Name __EEE25: #REF!
Name __EEE26: #REF!
Name __EEE27: #REF!
Name __EEE28: #REF!
Name __EEE29: #REF!
Name __EEE30: #REF!
Name __grv20: [1]BAHAN!$E$116
Name __grv30: [1]BAHAN!#REF!
Name __Ibr1: #REF!
Name __IV100000: #REF!
Name __kc3: [1]BAHAN!$E$192
Name __kc5: [1]BAHAN!$E$193
Name __LL01: #REF!
Name __LL02: #REF!
Name __LL03: #REF!
Name __LL04: #REF!
Name __LL05: #REF!
Name __LL06: #REF!
Name __LL07: #REF!
Name __LL08: #REF!
Name __LL09: #REF!
Name __lmb1: #REF!
Name __MB01: #REF!
Name __MB02: #REF!
Name __MB06: #REF!

Sheet RAB
K2: 6
B3: RENCANA ANGGARAN BIAYA ( RAB )
B4: KEGIATAN KONTRAKTUAL
B5: PROGRAM INFRASTRUKTUR BIDANG AIR MINUM TAHUN ANGGARAN 2026
B7: UNIT KERJA | F7: : | G7: DINAS PERUMAHAN DAN KAWASAN PERMUKIMAN KABUPATEN CIANJUR
B8: PROGRAM | F8: : | G8: PROGRAM PENGELOLAAN DAN PENGEMBANGAN SISTEM PENYEDIAAN AIR MINUM
B9: KEGIATAN | F9: : | G9: PENGELOLAAN DAN PENGEMBANGAN SISTEM PENYEDIAAN AIR MINUM (SPAM) DI DAERAH KABUPATEN/KOTA
B10: SUB KEGIATAN | F10: : | G10: PEMBANGUNAN SPAM BUKAN JARINGAN PERPIPAAN DI KAWASAN PERDESAAN
B11: PEKERJAAN | F11: : | G11: KURANGYA AIR BERSIH PESANTREN AL MARUF RT.03 RW.01 KP.BOBOJONG DESA BOBOJONG KECAMATAN MANDE
B12: LOKASI | F12: : | G12: PESANTREN AL MARUF RT.03 RW.01 KP.BOBOJONG DESA BOBOJONG KECAMATAN MANDE
B13: SUMBER DANA | F13: : | G13: DAU
B14: TAHUN ANGGARAN | F14: : | G14: 2026
B16: REKAPITULASI RENCANA ANGGARAN BIAYA ( RAB )
K17: Halaman : 1
B18: NO | C18: URAIAN PEKERJAAN | J18: JUMLAH HARGA
H19: SAT | I19: VOLUME
B22: =B79 -> I | C22: =+C79 -> PEKERJAAN PERSIAPAN | H22: Pkt | I22: 1 | J22: Rp. | K22: =K90 -> 3750000
B24: =B92 -> II | C24: =C92 -> PEMBUATAN SUMUR BOR (SATS) TYPE 49 M DIA. 6" | H24: Unit | I24: 1 | J24: Rp. | K24: =K120 -> 73904004
B26: =B122 -> III | C26: =C122 -> PENYAMBUNGAN LISTRIK PLN | H26: Unit | I26: 1 | J26: Rp. | K26: =K125 -> 4000000
B28: =B127 -> IV | C28: =+C127 -> PENGADAAN DAN PEMASANGAN PIPA DAN ASESORIS | H28: Pkt | I28: 1 | J28: Rp. | K28: =K205 -> 2364193.9
B30: =B255 -> V | C30: =C255 -> KRAN UMUM (KU) | H30: Unit | I30: 1 | J30: Rp. | K30: =K291 -> 5070270.4
B32: =B222 -> V | C32: =C222 -> PEKERJAAN SAMBUNGAN RUMAH | H32: Unit | I32: =I224 -> 0 | J32: Rp. | K32: =K253 -> 0
B34: =B293 -> V | C34: =C293 -> PEMBUATAN RESERVOIR 25 M3 | H34: Unit | I34: 1 | J34: Rp. | K34: =K342 -> 0
B36: =B344 -> VI | C36: =C344 -> PEKERJAAN PERLINTASAN ( CROSSING, JEMBATAN PIPA ) | H36: Unit | I36: 1 | J36: Rp. | K36: =K355 -> 0
B38: =B357 -> VI | C38: =C357 -> PENYELENGGARAAN SISTEM MANAJEMEN KESELAMATAN KONSTRUKSI (SMKK) | H38: Pkt | I38: 1 | J38: Rp. | K38: =K390 -> 1000000
C41: SUB JUMLAH | J41: Rp. | K41: =SUM(K22:K40) -> 90088469
C42: PPN 11% | J42: Rp. | K42: =+K41*0.11 -> 9909731.5
C43: JUMLAH | J43: Rp. | K43: =+K42+K41 -> 99998200
C44: DIBULATKAN | J44: Rp. | K44: =INT(K43/100)*100 -> 99998200 | L44: 100000000 | M44: PAGU
C45: DALAM HURUP | F45: : | G45: =UPPER([30]!terbilang(K44)&" RUPIAH") -> SEMBILAN PULUH SEMBILAN JUTA SEMBILAN RATUS SEMBILAN PULUH DELAPAN RIBU DUA RATUS RUPIAH | L45: =K44-L44 -> -1800
C47: JANGKA WAKTU PELAKSANAAN : 90 ( SEMBILAN PULUH ) HARI KALENDER
J50: Cianjur, 2026
J52: Disusun dan Ditetapkan Oleh :
J53: Kepala Bidang Air Minum dan Sanitasi
J54: Dinas Perumahan dan Kawasan Permukiman Kabupaten Cianjur
J55: Selaku Pejabat Pembuat Komitmen TA. 2025
J60: AGUNG DELI SAHPUTRA, ST
J61: NIP. 19771121 200604 1 010
B64: RENCANA ANGGARAN BIAYA ( RAB )
B66: UNIT KERJA | F66: : | G66: =G7 -> DINAS PERUMAHAN DAN KAWASAN PERMUKIMAN KABUPATEN CIANJUR
...

Sheet HARSAT
B3: DAFTAR HARGA SATUAN
B4: =RAB!B7 -> UNIT KERJA | E4: =RAB!F7 -> : | F4: =RAB!G7 -> DINAS PERUMAHAN DAN KAWASAN PERMUKIMAN KABUPATEN CIANJUR
B5: =RAB!B8 -> PROGRAM | E5: =RAB!F8 -> : | F5: =RAB!G8 -> PROGRAM PENGELOLAAN DAN PENGEMBANGAN SISTEM PENYEDIAAN AIR MINUM
B6: =RAB!B9 -> KEGIATAN | E6: =RAB!F9 -> : | F6: =RAB!G9 -> PENGELOLAAN DAN PENGEMBANGAN SISTEM PENYEDIAAN AIR MINUM (SPAM) DI DAERAH KABUPATEN/KOTA
B7: =RAB!B10 -> SUB KEGIATAN | E7: =RAB!F10 -> : | F7: =RAB!G10 -> PEMBANGUNAN SPAM BUKAN JARINGAN PERPIPAAN DI KAWASAN PERDESAAN
B8: =RAB!B11 -> PEKERJAAN | E8: =RAB!F11 -> : | F8: =RAB!G11 -> KURANGYA AIR BERSIH PESANTREN AL MARUF RT.03 RW.01 KP.BOBOJONG DESA BOBOJONG KECAMATAN MANDE
B9: =RAB!B12 -> LOKASI | E9: =RAB!F12 -> : | F9: =RAB!G12 -> PESANTREN AL MARUF RT.03 RW.01 KP.BOBOJONG DESA BOBOJONG KECAMATAN MANDE
B10: =RAB!B13 -> SUMBER DANA | E10: =RAB!F13 -> : | F10: =RAB!G13 -> DAU
B11: =RAB!B14 -> TAHUN ANGGARAN | E11: =RAB!F14 -> : | F11: =RAB!G14 -> 2026
H12: Halaman : 1
B13: NO | C13: URAIAN PEKERJAAN | G13: SATUAN | H13: HARGA SATUAN
H15: (Rp)
B17: 1 | C17: Pembuatan Bouwplank | G17: m' | H17: =ANALISA!N375 -> 21692.45
B18: =B17+1 -> 2 | C18: Galian tanah biasa | G18: m3 | H18: =ANALISA!N382 -> 18914.625
B19: =B18+1 -> 3 | C19: Galian tanah keras | G19: m3 | H19: =ANALISA!N410 -> 75204.25
B20: =B19+1 -> 4 | C20: Galian tanah berbatu, rabat dan aspal | G20: m3 | H20: =ANALISA!N417 -> 473141.05
B21: =B20+1 -> 5 | C21: Urugan pasir dipadatkan | G21: m3 | H21: =ANALISA!N425 -> 201508.75
B22: =B21+1 -> 6 | C22: Urugan tanah kembali | G22: m3 | H22: =ANALISA!N432 -> 27939.25
B23: =B22+1 -> 7 | C23: Pembuangan / perataan sisa galian | G23: m3 | H23: =ANALISA!N439 -> 36081.25
B24: =B23+1 -> 8 | C24: Pasangan batu kosong | G24: m3 | H24: =ANALISA!N449 -> 454244.25
B25: =B24+1 -> 9 | C25: Pasangan batu kali camp. 1 : 4 | G25: m3 | H25: =ANALISA!N460 -> 820280.05
B26: =B25+1 -> 10 | C26: =ANALISA!C469 -> Pas. Bata Merah ukuran (5x11x22) cm tebal ½ bata, campuran spesi 1PC : 3PS | G26: m2 | H26: =ANALISA!N479 -> 158779.81
B27: =B26+1 -> 11 | C27: Plesteran camp. 1 : 3 | G27: m2 | H27: =ANALISA!N489 -> 83800.5
B28: =B27+1 -> 12 | C28: =ANALISA!C490 -> Pas.Lantai Keramik uk. 25 x 25 cm (warna / corak) | G28: m2 | H28: =ANALISA!N502 -> 179348.25
B29: =B28+1 -> 13 | C29: =ANALISA!C503 -> Pas.Dinding Keramik uk. 25 x 40cm (warna / corak) | G29: m2 | H29: =ANALISA!N515 -> 218885.25
B30: =B29+1 -> 14 | C30: Pembuatan dan Pengecorn 1 m3 Campuran Beton fc' = 7.4 s.d 9.4 MPa (K-100 s.d K-125) untuk Lantai Kerja | G30: m3 | H30: =ANALISA!N528 -> 623929.13
B31: =B30+1 -> 15 | C31: Pembuatan dan Pengecorn 1 m3 Campuran Beton fc' = 9.8 MPa (K-125) untuk Lantai Kerja | G31: m3 | H31: =ANALISA!N540 -> 689697.71
B32: =B31+1 -> 16 | C32: Pembuatan dan Pengecorn 1 m3 Campuran Beton fc' = 12.2 MPa (K-150) untuk Komponen Struktur Utama dan Penunjang | G32: m3 | H32: =ANALISA!N552 -> 713941.36
B33: =B32+1 -> 17 | C33: Pembuatan dan Pengecorn 1 m3 Campuran Beton fc' = 14.5 MPa (K-175) untuk Komponen Struktur Utama dan Penunjang | G33: m3 | H33: =ANALISA!N564 -> 742088.43
B34: =B33+1 -> 18 | C34: Pembuatan dan Pengecorn 1 m3 Campuran Beton fc' = 16.9 MPa (K-200) untuk Komponen Struktur Utama dan Penunjang | G34: m3 | H34: =ANALISA!N576 -> 769851.07
B35: =B34+1 -> 19 | C35: Pembuatan dan Pengecorn 1 m3 Campuran Beton fc' = 19.3 MPa (K-225) untuk Komponen Struktur Utama dan Penunjang | G35: m3 | H35: =ANALISA!N588 -> 789386.29
B36: =B35+1 -> 20 | C36: Pembuatan dan Pengecorn 1 m3 Campuran Beton fc' = 21.7 MPa (K-250) untuk Komponen Struktur Utama dan Penunjang | G36: m3 | H36: =ANALISA!N600 -> 803978.14
B37: =B36+1 -> 21 | C37: Pembuatan dan Pengecorn 1 m3 Campuran Beton fc' = 24. MPa (K-275) untuk Komponen Struktur Utama dan Penunjang | G37: m3 | H37: =ANALISA!N612 -> 829176.29
B38: =B37+1 -> 22 | C38: Pembuatan dan Pengecorn 1 m3 Campuran Beton fc' = 26.4 MPa (K-300), kedap air normal untuk Komponen Struktur Utama dan Penunjang | G38: m3 | H38: =ANALISA!N624 -> 829176.29
B39: =B38+1 -> 23 | C39: Pembuatan dan Pengecorn 1 m3 Campuran Beton fc' = 28.8 MPa (K-325), kedap air normal untuk Komponen Struktur Utama dan Penunjang | G39: m3 | H39: =ANALISA!N636 -> 866505.29
B40: =B39+1 -> 24 | C40: Pembuatan dan Pengecorn 1 m3 Campuran Beton fc' = 31.2 MPa (K-350), kedap air agresif untuk Komponen Struktur Utama dan Penunjang | G40: m3 | H40: =ANALISA!N648 -> 876791.21
B41: =B40+1 -> 25 | C41: Pekerjaan Pembesian | G41: kg | H41: =ANALISA!N660 -> 19621.875
B42: =B41+1 -> 26 | C42: Pemasangan 1 m2 Bekisting untuk Pondasi Telapak Beton Bangunan (Termasuk Pembongkaran) | G42: m2 | H42: =ANALISA!N671 -> 33524.8
B43: =B42+1 -> 27 | C43: Pemasangan 1 m2 Bekisting untuk Sloof Beton Bangunan (Termasuk Pembongkaran) | G43: m2 | H43: =ANALISA!N681 -> 362560.5
B44: =B43+1 -> 28 | C44: Pemasangan 1 m2 Bekisting untuk Kolom Beton Bangunan (Termasuk Pembongkaran) | G44: m2 | H44: =ANALISA!N694 -> 501785.25
...

Sheet ANALISA
A3: DAFTAR ANALISA HARGA SATUAN
A4: =HARSAT!B4 -> UNIT KERJA | D4: =HARSAT!E4 -> : | E4: =HARSAT!F4 -> DINAS PERUMAHAN DAN KAWASAN PERMUKIMAN KABUPATEN CIANJUR
A5: =HARSAT!B5 -> PROGRAM | D5: =HARSAT!E5 -> : | E5: =HARSAT!F5 -> PROGRAM PENGELOLAAN DAN PENGEMBANGAN SISTEM PENYEDIAAN AIR MINUM
A6: =HARSAT!B6 -> KEGIATAN | D6: =HARSAT!E6 -> : | E6: =HARSAT!F6 -> PENGELOLAAN DAN PENGEMBANGAN SISTEM PENYEDIAAN AIR MINUM (SPAM) DI DAERAH KABUPATEN/KOTA
A7: =HARSAT!B7 -> SUB KEGIATAN | D7: =HARSAT!E7 -> : | E7: =HARSAT!F7 -> PEMBANGUNAN SPAM BUKAN JARINGAN PERPIPAAN DI KAWASAN PERDESAAN
A8: =HARSAT!B8 -> PEKERJAAN | D8: =HARSAT!E8 -> : | E8: =HARSAT!F8 -> KURANGYA AIR BERSIH PESANTREN AL MARUF RT.03 RW.01 KP.BOBOJONG DESA BOBOJONG KECAMATAN MANDE
A9: =HARSAT!B9 -> LOKASI | D9: =HARSAT!E9 -> : | E9: =HARSAT!F9 -> PESANTREN AL MARUF RT.03 RW.01 KP.BOBOJONG DESA BOBOJONG KECAMATAN MANDE
A10: =HARSAT!B10 -> SUMBER DANA | D10: =HARSAT!E10 -> : | E10: =HARSAT!F10 -> DAU
A11: =HARSAT!B11 -> TAHUN ANGGARAN | D11: =HARSAT!E11 -> : | E11: =HARSAT!F11 -> 2026
N12: Halaman : 1
A13: NO | B13: URAIAN PEKERJAAN | I13: SAT | J13: KOEF | K13: HARGA | L13: HARGA SATUAN | P13: Volume | Q13: Sat | R13: Tenaga Kerja | V13: Bahan Material
K14: SATUAN | L14: UPAH | M14: BAHAN | N14: JUMLAH HARGA | R14: Pekerja | S14: Tukang | T14: K.Tukang | U14: Mandor | V14: Psr.Pasang | W14: Psr.Betong | X14: Batu Pecah | Y14: Batu Belah | Z14: Semen | AA14: Kayu | AB14: Besi
K15: ( Rp ) | L15: ( Rp ) | M15: ( Rp ) | N15: ( Rp ) | P15: 1 | Q15: 2 | R15: 3 | S15: 4 | T15: 5 | U15: 6 | V15: 7 | W15: 8 | X15: 9 | Y15: 10 | Z15: 11 | AA15: 12 | AB15: 13 | AC15: 14 | AD15: 15
B17: ANALISA PEKERJAAN PENGEBORAN
A19: A | B19: SUMUR DALAM
A20: 1 | B20: 1 m' Pemboran Pilot Hole dia. 8"
C21: Lama Pekerjaan Pemboran per meter | I21: jam | J21: 1.1
B22: a. | C22: Biaya mesin bor dan accessories | I22: jam | J22: =J21 -> 1.1 | K22: ='BOR 8"'!J40 -> 173955.92 | L22: =J22*K22 -> 191351.52 | M22: - | N22: =L22+M22 -> 191351.52
B23: b. | C23: Biaya Personil
C24: - Geologist | D24: 1 | E24: Org | F24: x | G24: =$J$22 -> 1.1 | H24: jam | I24: Org/Jam | J24: =D24*G24 -> 1.1 | K24: ='UPAH BAHAN'!H28 -> 83500 | L24: =J24*K24 -> 91850 | M24: - | N24: =L24+M24 -> 91850
C25: - Site Supervisor | D25: 1 | E25: Org | F25: x | G25: =$J$22 -> 1.1 | H25: jam | I25: Org/Jam | J25: =D25*G25 -> 1.1 | K25: ='UPAH BAHAN'!H29 -> 68500 | L25: =J25*K25 -> 75350 | M25: - | N25: =L25+M25 -> 75350
C26: - Driller | D26: 1 | E26: Org | F26: x | G26: =$J$22 -> 1.1 | H26: jam | I26: Org/Jam | J26: =D26*G26 -> 1.1 | K26: ='UPAH BAHAN'!H30 -> 63500 | L26: =J26*K26 -> 69850 | M26: - | N26: =L26+M26 -> 69850
C27: - Ass. Driller | D27: 1 | E27: Org | F27: x | G27: =$J$22 -> 1.1 | H27: jam | I27: Org/Jam | J27: =D27*G27 -> 1.1 | K27: ='UPAH BAHAN'!H31 -> 54500 | L27: =J27*K27 -> 59950 | M27: - | N27: =L27+M27 -> 59950
C28: - Mekanik | D28: 1 | E28: Org | F28: x | G28: =$J$22 -> 1.1 | H28: jam | I28: Org/Jam | J28: =D28*G28 -> 1.1 | K28: ='UPAH BAHAN'!H32 -> 52000 | L28: =J28*K28 -> 57200 | M28: - | N28: =L28+M28 -> 57200
C29: - Crew Bor | D29: 4 | E29: Org | F29: x | G29: =$J$22 -> 1.1 | H29: jam | I29: Org/Jam | J29: =D29*G29 -> 4.4 | K29: ='UPAH BAHAN'!H33 -> 36500 | L29: =J29*K29 -> 160600 | M29: - | N29: =L29+M29 -> 160600
I30: Jumlah | L30: =SUM(L22:L29) -> 706151.52 | M30: - | N30: =SUM(N22:N29) -> 706151.52
I31: Over head & Profit 15 % | N31: =N30*15% -> 105922.73
I32: Total = Jumlah+(Keuntungan+Over head) | N32: =N30+N31 -> 812074.25
A33: =A20+1 -> 2 | B33: 1 m' Pemboran Reaming dari dia. 8" ke dia. 12"
C34: Lama Pekerjaan Pemboran per meter | I34: jam | J34: =J21*0.8 -> 0.88
B35: a. | C35: Biaya mesin bor dan accessories | I35: jam | J35: =J34 -> 0.88 | K35: =K22 -> 173955.92 | L35: =J35*K35 -> 153081.21 | M35: - | N35: =L35+M35 -> 153081.21
B36: b. | C36: Biaya Personil
C37: - Geologist | D37: 1 | E37: Org | F37: x | G37: =$J$35 -> 0.88 | H37: jam | I37: Org/Jam | J37: =D37*G37 -> 0.88 | K37: =K24 -> 83500 | L37: =J37*K37 -> 73480 | M37: - | N37: =L37+M37 -> 73480
C38: - Site Supervisor | D38: 1 | E38: Org | F38: x | G38: =$J$35 -> 0.88 | H38: jam | I38: Org/Jam | J38: =D38*G38 -> 0.88 | K38: =K25 -> 68500 | L38: =J38*K38 -> 60280 | M38: - | N38: =L38+M38 -> 60280
C39: - Driller | D39: 1 | E39: Org | F39: x | G39: =$J$35 -> 0.88 | H39: jam | I39: Org/Jam | J39: =D39*G39 -> 0.88 | K39: =K26 -> 63500 | L39: =J39*K39 -> 55880 | M39: - | N39: =L39+M39 -> 55880
C40: - Ass. Driller | D40: 1 | E40: Org | F40: x | G40: =$J$35 -> 0.88 | H40: jam | I40: Org/Jam | J40: =D40*G40 -> 0.88 | K40: =K27 -> 54500 | L40: =J40*K40 -> 47960 | M40: - | N40: =L40+M40 -> 47960
C41: - Mekanik | D41: 1 | E41: Org | F41: x | G41: =$J$35 -> 0.88 | H41: jam | I41: Org/Jam | J41: =D41*G41 -> 0.88 | K41: =K28 -> 52000 | L41: =J41*K41 -> 45760 | M41: - | N41: =L41+M41 -> 45760
C42: - Crew Bor | D42: 4 | E42: Org | F42: x | G42: =$J$35 -> 0.88 | H42: jam | I42: Org/Jam | J42: =D42*G42 -> 3.52 | K42: =K29 -> 36500 | L42: =J42*K42 -> 128480 | M42: - | N42: =L42+M42 -> 128480
I43: Jumlah | L43: =SUM(L35:L42) -> 564921.21 | M43: - | N43: =SUM(N35:N42) -> 564921.21
I44: Over head & Profit 15 % | N44: =N43*15% -> 84738.182
...

Sheet UPAH BAHAN
B3: DAFTAR HARGA SATUAN UPAH DAN BAHAN
B4: =ANALISA!A4 -> UNIT KERJA | E4: =ANALISA!D4 -> : | F4: =ANALISA!E4 -> DINAS PERUMAHAN DAN KAWASAN PERMUKIMAN KABUPATEN CIANJUR
B5: =ANALISA!A5 -> PROGRAM | E5: =ANALISA!D5 -> : | F5: =ANALISA!E5 -> PROGRAM PENGELOLAAN DAN PENGEMBANGAN SISTEM PENYEDIAAN AIR MINUM
B6: =ANALISA!A6 -> KEGIATAN | E6: =ANALISA!D6 -> : | F6: =ANALISA!E6 -> PENGELOLAAN DAN PENGEMBANGAN SISTEM PENYEDIAAN AIR MINUM (SPAM) DI DAERAH KABUPATEN/KOTA
B7: =ANALISA!A7 -> SUB KEGIATAN | E7: =ANALISA!D7 -> : | F7: =ANALISA!E7 -> PEMBANGUNAN SPAM BUKAN JARINGAN PERPIPAAN DI KAWASAN PERDESAAN
B8: =ANALISA!A8 -> PEKERJAAN | E8: =ANALISA!D8 -> : | F8: =ANALISA!E8 -> KURANGYA AIR BERSIH PESANTREN AL MARUF RT.03 RW.01 KP.BOBOJONG DESA BOBOJONG KECAMATAN MANDE
B9: =ANALISA!A9 -> LOKASI | E9: =ANALISA!D9 -> : | F9: =ANALISA!E9 -> PESANTREN AL MARUF RT.03 RW.01 KP.BOBOJONG DESA BOBOJONG KECAMATAN MANDE
B10: =ANALISA!A10 -> SUMBER DANA | E10: =ANALISA!D10 -> : | F10: =ANALISA!E10 -> DAU
B11: =ANALISA!A11 -> TAHUN ANGGARAN | E11: =ANALISA!D11 -> : | F11: =ANALISA!E11 -> 2026
B13: NO | C13: URAIAN UPAH DAN BAHAN | G13: SATUAN | H13: HARGA SATUAN
H15: (Rp)
B17: I | C17: HARGA UPAH
B19: 1 | C19: Pekerja | G19: Org / Hari | H19: 105000 | I19: 75000
B20: =B19+1 -> 2 | C20: Tukang batu | G20: Org / Hari | H20: 135000 | I20: 120000
B21: =B20+1 -> 3 | C21: Tukang kayu | G21: Org / Hari | H21: 135000 | I21: =+I20 -> 120000
B22: =B21+1 -> 4 | C22: Tukang besi | G22: Org / Hari | H22: 135000 | I22: =+I21 -> 120000
B23: =B22+1 -> 5 | C23: Tukang pipa | G23: Org / Hari | H23: 135000 | I23: =+I22 -> 120000
B24: =B23+1 -> 6 | C24: Mandor | G24: Org / Hari | H24: 165000 | I24: 150000
B25: =B24+1 -> 7 | C25: Kepala Tukang | G25: Org / Hari | H25: 150000 | I25: 125000 | J25: =H25*0.15 -> 22500 | K25: =J25+H25 -> 172500
B26: =B25+1 -> 8 | C26: Penjaga | G26: Org / Hari | H26: 100000 | I26: 100000
B27: =B26+1 -> 9 | C27: Masinis | G27: Org / Hari | H27: 170000 | I27: 170000
B28: =B27+1 -> 10 | C28: Geologist | G28: Org / Jam | H28: 83500 | I28: 83500
B29: =B28+1 -> 11 | C29: Site Supervisor | G29: Org / Jam | H29: 68500 | I29: 68500
B30: =B29+1 -> 12 | C30: Driller | G30: Org / Jam | H30: 63500 | I30: 63500
B31: =B30+1 -> 13 | C31: Ass. Driller | G31: Org / Jam | H31: 54500 | I31: 54500
B32: =B31+1 -> 14 | C32: Mekanik | G32: Org / Jam | H32: 52000 | I32: 52000
B33: =B32+1 -> 15 | C33: Crew Bor | G33: Org / Jam | H33: 36500 | I33: 36500
B35: II | C35: HARGA BAHAN
B37: 1 | C37: Pasir Urug | G37: m³ | H37: 130000 | I37: 200000
B38: =B37+1 -> 2 | C38: Pasir Pasang | G38: m³ | H38: 250000 | I38: 250000
B39: =B38+1 -> 3 | C39: Pasir Beton | G39: m³ | H39: 250000 | I39: 350000
B40: =B39+1 -> 4 | C40: Split beton | G40: m³ | H40: 180000 | I40: 300000 | J40: 300000
B41: =B40+1 -> 5 | C41: Semen (PC) | G41: zak | H41: 56000 | I41: 85000 | J41: 85000
B42: =B41+1 -> 6 | C42: Batu Belah | G42: m³ | H42: 160000 | I42: 260000
B43: =B42+1 -> 7 | C43: Bata merah | G43: bh | H43: 900
B44: =B43+1 -> 8 | C44: Bata Ringan (Heble) uk.10x20x60 cm | G44: bh | H44: 6000
B45: =B44+1 -> 9 | C45: Keramik 25 x 25 cm (KM) Kw1 DN warna/corak | G45: m2 | H45: 45000
B46: =B45+1 -> 10 | C46: Keramik 25 x 40 cm (KM) Kw1 DN warna/corak | G46: m2 | H46: 45000
B47: =B46+1 -> 11 | C47: Besi Beton | G47: Kg | H47: 11000 | I47: 17500
B48: =B47+1 -> 12 | C48: Gravel Pack (Kerikil Jagung) | G48: m3 | H48: 145000 | I48: 145000
...

Sheet JADWAL
B3: RENCANA JADWAL UNTUK PELAKSANAAN PEKERJAAN
B5: =RAB!B7 -> UNIT KERJA | D5: : | E5: =RAB!G7 -> DINAS PERUMAHAN DAN KAWASAN PERMUKIMAN KABUPATEN CIANJUR
B6: =RAB!B8 -> PROGRAM | D6: : | E6: =RAB!G8 -> PROGRAM PENGELOLAAN DAN PENGEMBANGAN SISTEM PENYEDIAAN AIR MINUM
B7: =RAB!B9 -> KEGIATAN | D7: : | E7: =RAB!G9 -> PENGELOLAAN DAN PENGEMBANGAN SISTEM PENYEDIAAN AIR MINUM (SPAM) DI DAERAH KABUPATEN/KOTA
B8: =RAB!B10 -> SUB KEGIATAN | D8: : | E8: =RAB!G10 -> PEMBANGUNAN SPAM BUKAN JARINGAN PERPIPAAN DI KAWASAN PERDESAAN
B9: =RAB!B11 -> PEKERJAAN | D9: : | E9: =RAB!G11 -> KURANGYA AIR BERSIH PESANTREN AL MARUF RT.03 RW.01 KP.BOBOJONG DESA BOBOJONG KECAMATAN MANDE
B10: =RAB!B12 -> LOKASI | D10: : | E10: =RAB!G12 -> PESANTREN AL MARUF RT.03 RW.01 KP.BOBOJONG DESA BOBOJONG KECAMATAN MANDE
B11: =RAB!B13 -> SUMBER DANA | D11: : | E11: =RAB!G13 -> DAU
B12: =RAB!B14 -> TAHUN ANGGARAN | D12: : | E12: =RAB!G14 -> 2026
H14: HARGA | I14: JUMLAH | J14: BOBOT | K14: WAKTU PELAKSANAAN | AC14: KET
B15: NO | C15: URAIAN PEKERJAAN | F15: VOL | G15: SAT | H15: SATUAN | I15: HARGA | K15: MINGGU KE
H16: ( Rp. ) | I16: ( Rp. ) | J16: ( %. ) | K16: 1 | L16: 2 | M16: 3 | N16: 4 | O16: 5 | P16: 6 | Q16: 7 | R16: 8 | S16: 9 | T16: 10 | U16: 11 | V16: 12 | W16: 13 | X16: 14 | Y16: 15 | Z16: 16 | AA16: 17 | AB16: 18
B18: =RAB!B22 -> I | C18: =RAB!C22 -> PEKERJAAN PERSIAPAN | F18: =RAB!I22 -> 1 | G18: =RAB!H22 -> Pkt | H18: =RAB!K22 -> 3750000 | I18: =H18 -> 3750000 | J18: =I18/$I$26*100 -> 4.6285897 | K18: =+J18/18 -> 0.25714387 | L18: =+K18 -> 0.25714387 | M18: =+L18 -> 0.25714387 | N18: =+M18 -> 0.25714387 | O18: =+N18 -> 0.25714387 | P18: =+O18 -> 0.25714387 | Q18: =+P18 -> 0.25714387 | R18: =+Q18 -> 0.25714387 | S18: =+R18 -> 0.25714387 | ... AB18: =+AA18 -> 0.25714387
B19: =RAB!B38 -> VI | C19: =RAB!C38 -> PENYELENGGARAAN SISTEM MANAJEMEN KESELAMATAN KONSTRUKSI (SMKK) | F19: =RAB!I24 -> 1 | G19: =RAB!H24 -> Unit | H19: =RAB!K24 -> 73904004 | I19: =H19 -> 73904004 | J19: =I19/$I$26*100 -> 91.219017 | K19: =+J19/18 -> 5.0677232 | L19: =+K19 -> 5.0677232 | M19: =+L19 -> 5.0677232 | N19: =+M19 -> 5.0677232 | O19: =+N19 -> 5.0677232 | P19: =+O19 -> 5.0677232 | Q19: =+P19 -> 5.0677232 | R19: =+Q19 -> 5.0677232 | S19: =+R19 -> 5.0677232 | ... AB19: =+AA19 -> 5.0677232
B20: =RAB!B28 -> IV | C20: =RAB!C28 -> PENGADAAN DAN PEMASANGAN PIPA DAN ASESORIS | F20: =RAB!I28 -> 1 | G20: =RAB!H28 -> Pkt | H20: =RAB!K28 -> 2364193.9 | I20: =H20 -> 2364193.9 | J20: =I20/$I$26*100 -> 2.9181023 | P20: =J20/7 -> 0.41687176 | Q20: =P20 -> 0.41687176 | R20: =Q20 -> 0.41687176 | S20: =R20 -> 0.41687176 | T20: =S20 -> 0.41687176 | U20: =T20 -> 0.41687176 | V20: =U20 -> 0.41687176
B21: =RAB!B32 -> V | C21: =RAB!C32 -> PEKERJAAN SAMBUNGAN RUMAH | F21: =RAB!I32 -> 0 | G21: =RAB!H32 -> Unit | H21: =RAB!K32 -> 0 | I21: =H21 -> 0 | J21: =I21/$I$26*100 -> 0 | W21: =J21/5 -> 0 | X21: =W21 -> 0 | Y21: =+X21 -> 0 | Z21: =+Y21 -> 0 | AA21: =+Z21 -> 0
B22: =RAB!B34 -> V | C22: =RAB!C34 -> PEMBUATAN RESERVOIR 25 M3 | F22: =RAB!I34 -> 1 | G22: =RAB!H34 -> Unit | H22: =RAB!K34 -> 0 | I22: =H22 -> 0 | J22: =I22/$I$26*100 -> 0 | M22: =J22/3 -> 0 | N22: =M22 -> 0 | O22: =N22 -> 0
B23: =RAB!B36 -> VI | C23: =RAB!C36 -> PEKERJAAN PERLINTASAN ( CROSSING, JEMBATAN PIPA ) | F23: =RAB!I36 -> 1 | G23: =RAB!H36 -> Unit | H23: =RAB!K36 -> 0 | I23: =H23 -> 0 | J23: =I23/$I$26*100 -> 0 | R23: =J23 -> 0
B24: =RAB!B38 -> VI | C24: =RAB!C38 -> PENYELENGGARAAN SISTEM MANAJEMEN KESELAMATAN KONSTRUKSI (SMKK) | F24: =RAB!I38 -> 1 | G24: =RAB!H38 -> Pkt | H24: =RAB!K38 -> 1000000 | I24: =H24 -> 1000000 | J24: =I24/$I$26*100 -> 1.2342906 | K24: =+J24/18 -> 0.0685717 | L24: =+K24 -> 0.0685717 | M24: =+L24 -> 0.0685717 | N24: =+M24 -> 0.0685717 | O24: =+N24 -> 0.0685717 | P24: =+O24 -> 0.0685717 | Q24: =+P24 -> 0.0685717 | R24: =+Q24 -> 0.0685717 | S24: =+R24 -> 0.0685717 | ... AB24: =+AA24 -> 0.0685717
C26: JUMLAH | I26: =SUM(I18:I25) -> 81018198 | J26: =SUM(J18:J25) -> 100
C27: RENCANA KEMAJUAN PER MINGGU (%) | K27: =SUM(K18:K25) -> 5.3934388 | L27: =SUM(L18:L25) -> 5.3934388 | M27: =SUM(M18:M25) -> 5.3934388 | N27: =SUM(N18:N25) -> 5.3934388 | O27: =SUM(O18:O25) -> 5.3934388 | P27: =SUM(P18:P25) -> 5.8103105 | Q27: =SUM(Q18:Q25) -> 5.8103105 | R27: =SUM(R18:R25) -> 5.8103105 | ... AB27: =SUM(AB18:AB25) -> 5.3934388
C28: KUMULATIF KEMAJUAN PER MINGGU (%) | K28: =K27 -> 5.3934388 | L28: =K28+L27 -> 10.786878 | M28: =L28+M27 -> 16.180316 | N28: =M28+N27 -> 21.573755 | O28: =N28+O27 -> 26.967194 | P28: =O28+P27 -> 32.777504 | Q28: =P28+Q27 -> 38.587815 | R28: =Q28+R27 -> 44.398125 | S28: =R28+S27 -> 50.208436 | ... AB28: =AA28+AB27 -> 100
C30: =RAB!C47 -> JANGKA WAKTU PELAKSANAAN : 90 ( SEMBILAN PULUH ) HARI KALENDER | W30: =RAB!J50 -> Cianjur, 2026
C31: MASA PEMELIHARAAN PEKERJAAN = 180 (SERATUS DELAPAN PULUH) HARI KALENDER
W32: =RAB!J52 -> Disusun dan Ditetapkan Oleh :
W33: =RAB!J53 -> Kepala Bidang Air Minum dan Sanitasi
W34: =RAB!J54 -> Dinas Perumahan dan Kawasan Permukiman Kabupaten Cianjur
W35: =RAB!J55 -> Selaku Pejabat Pembuat Komitmen TA. 2025
W40: =RAB!J60 -> AGUNG DELI SAHPUTRA, ST
W41: =RAB!J61 -> NIP. 19771121 200604 1 010

Sheet ANALISA SR
B2: 37 | C2: 1 Unit Pekerjaan Sambungan Rumah (SR) Type -1 (Dia.32)
B3: NO. | C3: URAIAN | E3: KODE | F3: SATUAN | G3: KOEFISIEN | H3: HARGA | I3: JUMLAH
H4: SATUAN | I4: HARGA
H5: ( Rp ) | I5: ( Rp )
B7: A. | C7: TENAGA
C9: Biaya onkos sambungan rumah | F9: Ls | G9: 1 | H9: =RAB!J251 -> 150000 | I9: =H9*G9 -> 150000
G11: JUMLAH HARGA TENAGA | I11: =SUM(I9:I10) -> 150000
B13: B. | C13: BAHAN | G13: 1
C15: Pengadaan pipa dan accessories sambungan rumah
C16: - | D16: Pipa GI dia. 1/2" Klass Medium | F16: m' | G16: =G13*1.5 -> 1.5 | H16: =RAB!J225 -> 54510 | I16: =H16*G16 -> 81765
C17: - | D17: Pipa PVC dia. 1/2" S.10 | F17: m' | G17: =G13*6 -> 6 | H17: =RAB!J226 -> 10670 | I17: =H17*G17 -> 64020
C18: - | D18: Clamp sadle GI dia. 2" x 1/2" | F18: bh | H18: =RAB!J227 -> 78200 | I18: =H18*G18 -> 0
C19: - | D19: Clamp sadle GI dia. 1 1/2" x 1/2" | F19: bh | H19: =RAB!J228 -> 64400 | I19: =H19*G19 -> 0
C20: - | D20: Tee PVC dia. 1" x 1/2" | F20: bh | G20: =G13-G19 -> 1 | H20: =RAB!J229 -> 27000 | I20: =H20*G20 -> 27000
C21: - | D21: Reducer PVC dia. 1" x 1/2" | F21: bh | H21: =RAB!J230 -> 9775 | I21: =H21*G21 -> 0
C22: - | D22: Valve socket PVC dia. 1/2" | F22: bh | H22: =RAB!J231 -> 7475 | I22: =H22*G22 -> 0
C23: - | D23: Knee GI dia. 1/2" | F23: bh | G23: =G13*5 -> 5 | H23: =RAB!J232 -> 8100 | I23: =H23*G23 -> 40500
C24: - | D24: Knee PVC dia. 1/2" | F24: bh | G24: =G13*1 -> 1 | H24: =RAB!J233 -> 6325 | I24: =H24*G24 -> 6325
C25: - | D25: Soket Drat Luar PVC dia. 1/2" (SDL) | F25: bh | G25: =G13*1 -> 1 | H25: =RAB!J234 -> 4140 | I25: =H25*G25 -> 4140
C26: - | D26: Elbow GI ( F/M ) dia. 1/2" | F26: bh | H26: =RAB!J235 -> 15525 | I26: =H26*G26 -> 0
C27: - | D27: Double Nipple GI dia. 1/2" | F27: bh | G27: =G13*3 -> 3 | H27: =RAB!J236 -> 6700 | I27: =H27*G27 -> 20100
C28: - | D28: Chek Valve dia. 1/2" | F28: bh | G28: 1 | H28: =RAB!J237 -> 96000 | I28: =H28*G28 -> 96000
C29: - | D29: =HARSAT!C269 -> Brass Loockable Ball Valve dia. 1/2" | F29: bh | G29: 1 | H29: =HARSAT!H269 -> 120884.55 | I29: =H29*G29 -> 120884.55
C30: - | D30: Brass Main Cock ( Plug Kran ) dia. 1/2" | F30: bh | H30: =RAB!J238 -> 92000 | I30: =H30*G30 -> 0
C31: - | D31: Brass Gate Valve ( Fiet Kran ) dia. 1/2" | F31: bh | G31: =G13*1 -> 1 | H31: =RAB!J239 -> 197000 | I31: =H31*G31 -> 197000
C32: - | D32: Water meter dengan coupling dia. 1/2" | F32: bh | G32: =G13*1 -> 1 | H32: =RAB!J240 -> 448000 | I32: =H32*G32 -> 448000
C33: - | D33: Tee GI dia. 1/2" x 1/2" | F33: bh | G33: =G13*1 -> 1 | H33: =RAB!J241 -> 15800 | I33: =H33*G33 -> 15800
C34: - | D34: Dop GI dia. 1/2" | F34: bh | G34: =G13*1 -> 1 | H34: =RAB!J242 -> 5175 | I34: =H34*G34 -> 5175
C35: - | D35: House Hold Tap ( Tap Kran ) dia. 1/2" | F35: bh | G35: =G13*1 -> 1 | H35: =RAB!J243 -> 65000 | I35: =H35*G35 -> 65000
C36: - | D36: Seal tape | F36: bh | G36: =G13*1.5 -> 1.5 | H36: =RAB!J244 -> 4600 | I36: =H36*G36 -> 6900
C37: - | D37: Box SR | F37: bh | G37: =G13*1 -> 1 | H37: =RAB!J245 -> 77000 | I37: =H37*G37 -> 77000
C38: - | D38: Rabat Beton Dudukan Box SR | F38: bh | G38: =G13*1 -> 1 | H38: =RAB!J246 -> 34500 | I38: =H38*G38 -> 34500
G40: JUMLAH HARGA BAHAN | I40: =SUM(I15:I39) -> 1310109.6
B42: C. | C42: PERALATAN
G44: JUMLAH HARGA PERALATAN | I44: 0
B46: D. | C46: JUMLAH HARGA TENAGA, BAHAN DAN PERALATAN ( A + B + C ) | I46: =I44+I40+I11 -> 1460109.6
B47: E. | C47: OVERHEAD & PROFIT | F47: 15 | G47: % x D
B48: F. | C48: HARGA SATUAN PEKERJAAN ( D + E )
B49: G | C49: DIBULATKAN

Sheet SMKK
B2: SISTEM MANAJEMEN KESELAMATAN KONSTRUKSI (SMKK)
B4: Sumber : PERMEN PUPR No. 10 Tahun Tahun 2021 Tentang Pedoman Sistem Manajemen Keselamatan Konstruksi
B7: NO. | C7: URAIAN PEKERJAAN | F7: SATUAN PEMBAYARAN | G7: KUANTITAS | H7: HARGA SATUAN (RP.) | I7: TOTAL HARGA (RP.) | J7: KETERANGAN | L7: NILAI TKDN | M7: HARGA TKDN
B8: 1 | C8: 2 | F8: 3 | G8: 4 | H8: 5 | I8: 6 = 4 * 5 | J8: 7 | L8: 8 | M8: 9
B10: I. | C10: PENYIAPAN RKK:
C11: a. | D11: Pembuatan Dokumen Rencana Keselamatan Konstruksi | F11: Set | G11: 1 | H11: 200000 | I11: =G11*H11 -> 200000 | J11: Memperhatikan jumlah dan jenis pekerjaan yang dikerjakan | L11: 0 | M11: =H11*L11 -> 0
C12: b. | D12: Pembuatan Prosedur dan Instruksi Kerja | F12: Set
C13: c. | D13: Penyiapan Formulir | F13: Set
C14: A. | D14: Sub Total Penyiapan RKK | I14: =SUM(I11) -> 200000 | M14: =SUM(M11) -> 0
B16: II. | C16: SOSIALISASI, PROMOSI, DAN PELATIHAN:
C17: a. | D17: Induksi K3 (Safety Induction) | F17: Org | G17: 4 | H17: 10000 | I17: =G17*H17 -> 40000 | J17: Memperhatikan perkiraan jumlah pekerja, tamu, dan staf | L17: 0 | M17: =H17*L17 -> 0
C18: b. | D18: Pertemuan Keselamatan (Safety Talk dan / atau Tool Box Meeting) | F18: Org | G18: =G17 -> 4 | H18: 10000 | I18: =G18*H18 -> 40000 | J18: Memperhatikan perkiraan jumlah pekerja dan risiko k3 pekerjaan | L18: 0 | M18: =H18*L18 -> 0
C19: c | D19: Spanduk (banner) | F19: Lbr | H19: ='[36]HARGA BAHAN & ALAT'!$F$189 -> 135900 | I19: =G19*H19 -> 0 | J19: Memperhatikan lokasi pekerjaan dan waktu pekerjaan | L19: ='[36]HARGA BAHAN & ALAT'!H189 -> #REF! | M19: =H19*L19 -> #REF!
C20: d. | D20: Poster | F20: Lbr | H20: ='[36]HARGA BAHAN & ALAT'!$F$168 -> 14000 | I20: =G20*H20 -> 0 | J20: Memperhatikan lokasi pekerjaan dan waktu pekerjaan | L20: ='[36]HARGA BAHAN & ALAT'!H168 -> #REF! | M20: =H20*L20 -> #REF!
C21: e. | D21: Papan Informasi K3 | F21: Bh | G21: 0 | H21: ='[36]HARGA BAHAN & ALAT'!$F$169 -> 426000 | I21: =G21*H21 -> 0 | J21: Memperhatikan risiko k3 pekerjaan | L21: ='[36]HARGA BAHAN & ALAT'!J169 -> 0 | M21: =H21*L21 -> 0
C22: B. | D22: Sub Total Sosialisasi, Promosi dan Pelatihan | I22: =SUM(I17:I21) -> 80000 | M22: =SUM(M17:M21) -> #REF!
B24: III. | C24: ALAT PELINDUNG KERJA (APK) DAN ALAT PELINDUNG DIRI (APD):
C25: a. | D25: APK Antara Lain:
D26: 1 | E26: Pembatas Area (Restricted Area) / Safety Line | F26: Bh | H26: ='[36]HARGA BAHAN & ALAT'!F170 -> 34000 | I26: =G26*H26 -> 0 | J26: Sesuai kebutuhan | L26: ='[36]HARGA BAHAN & ALAT'!J170 -> 0 | M26: =H26*L26 -> 0
C27: b. | D27: APD Antara Lain:
D28: 1 | E28: Topi Pelindung (Safety Helmet) | F28: Bh | G28: =G18 -> 4 | H28: 25000 | I28: =G28*H28 -> 100000 | J28: Memperhatikan perkiraan jumlah pekerja tamu dan staf | L28: ='[36]HARGA BAHAN & ALAT'!H171 -> 0.7112 | M28: =H28*L28 -> 17780 | N28: https://tkdn.kemenperin.go.id/sertifikat_perush.php?id=LXgDzIgDALi1Ge2ukHE7ZXx53avqEQjgBFBeb1z21ps,&id_siinas=LXgDzIgDALi1Ge2ukHE7ZXx53avqEQjgBFBeb1z21ps,
D29: 2 | E29: Sarung Tangan (Safety Gloves) | F29: Psg | G29: =G28 -> 4 | H29: 10000 | I29: =G29*H29 -> 40000 | J29: Sesuai kebutuhan | L29: ='[36]HARGA BAHAN & ALAT'!H175 -> 0.3263 | M29: =H29*L29 -> 3263 | N29: https://tkdn.kemenperin.go.id/sertifikat_perush.php?id=w-Y65P5c9W2YTOjPtMbiggEIxZYqgOC_2uf6vZXvY1s,&id_siinas=vq2DN3VwRxHs25X0BxmbQiFY8n_irbYjEg-5_LMePFo,
D30: 3 | E30: Sepatu Keselamatan (Safety Shoes) | F30: Psg | G30: =G29 -> 4 | H30: 87500 | I30: =G30*H30 -> 350000 | J30: Memperhatikan perkiraan jumlah pekerja tamu dan staf | L30: ='[36]HARGA BAHAN & ALAT'!H176 -> 0.8695 | M30: =H30*L30 -> 76081.25 | N30: https://tkdn.kemenperin.go.id/sertifikat_perush.php?id=qlXiOPwQVC1Ugd23hMrAjlt4wrfHvpLDs0C4F-q3-1E,&id_siinas=ajfIiFxWAc5tzDubq0-dX0MfNpFQ5ktPydWY9IqmyXk,
D31: 4 | E31: Rompi Keselamatan (Safety Vest) | F31: Bh | G31: =G30 -> 4 | H31: 10000 | I31: =G31*H31 -> 40000 | J31: Sesuai kebutuhan | L31: ='[36]HARGA BAHAN & ALAT'!H188 -> 0.7122 | M31: =H31*L31 -> 7122 | N31: https://tkdn.kemenperin.go.id/sertifikat_perush.php?id=BwjfXmFNy_PcPmlGSjWRfwFf_0CbZkh4h9MFN_ZqS8A,&id_siinas=cKhWiTRLRcHuRXFwucFMztay0TF-lws89_R8XrROL5Y,
C32: C. | D32: Sub Total Alat Pelindung Kerja dan Alat Pelindung Diri | I32: =SUM(I25:I31) -> 530000
B34: IV. | C34: ASURANSI DAN PERIZINAN:
C35: a. | D35: Asuransi JKK dan JKM | F35: Ls | H35: 600000 | I35: =G35*H35 -> 0 | L35: ='[36]HARGA BAHAN & ALAT'!H187 -> #REF! | M35: =H35*L35 -> #REF!
C36: D. | D36: Sub Total Asuransi dan Perizinan | I36: =SUM(I35:I35) -> 0 | M36: =SUM(M35:M35) -> #REF!
B38: V. | C38: PERSONEL K3 KONSTRUKSI:
C39: E. | D39: Sub Total Personel K3 Konstruksi | M39: =SUM(#REF!) -> #REF!
B41: VI. | C41: FASILITAS, SARANA DAN PRASARANA KESEHATAN:
C42: a. | D42: Peralatan P3K Umum (Kotak P3K, Obat Luka, Perban,dll) | F42: Ls | G42: 1 | H42: 190000 | I42: =G42*H42 -> 190000 | J42: Memperhatikan perkiraan jumlah pekerja dan risiko k3 pekerjaan | L42: ='[36]HARGA BAHAN & ALAT'!H178 -> 0 | M42: =H42*L42 -> 0
C43: F. | D43: Sub Total Fasilitas, Sarana, dan Prasarana Kesehatan | I43: =SUM(I42:I42) -> 190000 | M43: =SUM(M42:M42) -> 0
B45: VII. | C45: RAMBU-RAMBU YANG DIPERLUKAN:
C46: a. | D46: Rambu Petunjuk | F46: Bh | H46: ='[36]HARGA BAHAN & ALAT'!$F$179 -> 133200 | I46: =G46*H46 -> 0 | J46: Sesuai kebutuhan | L46: ='[36]HARGA BAHAN & ALAT'!$H$179 -> 0.4102 | M46: =H46*L46 -> 54638.64 | N46: https://tkdn.kemenperin.go.id/sertifikat_perush.php?id=QSsoMNgrkDEYcCxSuXBQOYxgtTtMbAZEyUEZIjoHkeM,&id_siinas=e_LvgcF-xqow-MxHTRxjI-78147nnLCAUxKl7HxUfnc,
C47: b. | D47: Rambu Larangan | F47: Bh | H47: ='[36]HARGA BAHAN & ALAT'!$F$179 -> 133200 | I47: =G47*H47 -> 0 | J47: Sesuai kebutuhan | L47: ='[36]HARGA BAHAN & ALAT'!$H$179 -> 0.4102 | M47: =H47*L47 -> 54638.64 | N47: https://tkdn.kemenperin.go.id/sertifikat_perush.php?id=QSsoMNgrkDEYcCxSuXBQOYxgtTtMbAZEyUEZIjoHkeM,&id_siinas=e_LvgcF-xqow-MxHTRxjI-78147nnLCAUxKl7HxUfnc,
C48: c. | D48: Rambu Peringatan | F48: Bh | H48: ='[36]HARGA BAHAN & ALAT'!$F$179 -> 133200 | I48: =G48*H48 -> 0 | J48: Sesuai kebutuhan | L48: ='[36]HARGA BAHAN & ALAT'!$H$179 -> 0.4102 | M48: =H48*L48 -> 54638.64 | N48: https://tkdn.kemenperin.go.id/sertifikat_perush.php?id=QSsoMNgrkDEYcCxSuXBQOYxgtTtMbAZEyUEZIjoHkeM,&id_siinas=e_LvgcF-xqow-MxHTRxjI-78147nnLCAUxKl7HxUfnc,
C49: d. | D49: Rambu Kewajiban | F49: Bh | H49: ='[36]HARGA BAHAN & ALAT'!$F$179 -> 133200 | I49: =G49*H49 -> 0 | J49: Sesuai kebutuhan | L49: ='[36]HARGA BAHAN & ALAT'!$H$179 -> 0.4102 | M49: =H49*L49 -> 54638.64 | N49: https://tkdn.kemenperin.go.id/sertifikat_perush.php?id=QSsoMNgrkDEYcCxSuXBQOYxgtTtMbAZEyUEZIjoHkeM,&id_siinas=e_LvgcF-xqow-MxHTRxjI-78147nnLCAUxKl7HxUfnc,
C50: G. | D50: Sub Total Rambu-rambu yang Diperlukan | I50: =SUM(I46:I49) -> 0
B52: VIII. | C52: KONSULTASI DENGAN AHLI TERKAIT KESELAMATAN KONSTRUKSI:
...

Sheet Sheet1
C4: Network Table - Nodes
B5: No | C5: =I6 -> Node ID | D5: Demand | E5: Head | F5: Pressure
D6: LPS | E6: m | F6: m | I6: Node ID
B7: 1 | C7: Junc J1 | D7: 0.00 | E7: 285.99 | F7: 1.99
B8: 2 | C8: Junc J2 | D8: 0.20 | E8: 285.97 | F8: 4.97
B9: 3 | C9: Junc J3 | D9: 0.00 | E9: 285.97 | F9: 5.97
B10: 4 | C10: Junc J4 | D10: 0.22 | E10: 285.88 | F10: 5.88
B11: 5 | C11: Junc J5 | D11: 0.00 | E11: 289.74 | F11: 8.74
B12: 6 | C12: Resvr R1 | D12: -25.01 | E12: 261.00 | F12: 0.00
B13: 7 | C13: Resvr R2 | D13: 24.59 | E13: 286.00 | F13: 0.00

Sheet BOR 8"
B3: NO | C3: U R A I A N | I3: HARGA SATUAN | J3: JUMLAH HARGA
I5: (Rp) | J5: (Rp)
B7: II. | C7: ANALISA PEKERJAAN PENGEBORAN
B9: A. | C9: DRILLING RIG
C11: Merk/Produksi | D11: : | E11: LONG YEARD 44 ( DRILLING RIG, PISTON PUMP )
C12: Type/Model | D12: : | E12: SKID MOUNTED
C13: Umur Ekonomi | D13: : | E13: a..................... | H13: 3 | I13: tahun
C14: Jam Kerja Pertahun | D14: : | E14: b..................... | H14: 2500 | I14: jam
C15: Harga Dasar Alat | D15: : | E15: A..................... | I15: 450000000 | K15: =[37]HARSAT!G35 -> 743325.29
C16: Nilai Depresiasi | D16: : | E16: B = A x 10 % ......... | I16: =I15*0.1 -> 45000000
C17: Nilai Sisa | D17: : | E17: C = A - B ............ | I17: =I15-I16 -> 405000000
C18: Data-Data Peralatan : | D18: :
C19: - HP/Berat | D19: : | E19: =100/2 -> 50 | F19: PK
C20: - Oli Mesin | D20: : | E20: =10/2 -> 5 | F20: Liter
C21: - Oli Gardan | D21: : | E21: =20/2 -> 10 | F21: Liter
C22: - Oli Transmisi | D22: : | E22: =20/2 -> 10 | F22: Liter
C23: - Oli Hidrolik | D23: : | E23: =90/2 -> 45 | F23: Liter
C25: Biaya Peralatan | D25: :
C26: a. Direct Cost ( Biaya Langsung ) perjam
C28: 1. Depresiasi
C29: 2. Biaya pemilikan, Asuransi, Pajak dll. = C : (a x b) | J29: =I17/(H13*H14) -> 54000
C30: 3. Biaya operasi peralatan perjam = 25 % x (a+1) : 2a x (A:b) | J30: =(((0.25*(H13+1))/(2*H13)))*(I15/H14) -> 30000
C31: a. Bahan Bakar | D31: = | E31: 0.15 | F31: x | G31: =E19 -> 50 | H31: Ltr | I31: 6800 | J31: =E31*G31*I31 -> 51000 | K31: 0.15
C32: b. Pelumas Mesin | D32: = | E32: =E20/200 -> 0.025 | F32: x | G32: =E19/G31 -> 1 | H32: Ltr | I32: 9750 | J32: =E32*G32*I32 -> 243.75 | K32: 10 | L32: / | M32: 200
C33: c. Pelumas Gardan | D33: = | E33: =E21/250 -> 0.04 | F33: x | G33: 1.2 | H33: Ltr | I33: 9750 | J33: =E33*G33*I33 -> 468 | K33: 20 | L33: / | M33: 250
C34: d. Pelumas Hidrolik | D34: = | E34: =E23/450 -> 0.1 | F34: x | G34: 1.2 | H34: Ltr | I34: 7750 | J34: =E34*G34*I34 -> 930 | K34: 90 | L34: / | M34: 450
C35: e. Stemfet/Graese | D35: = | G35: 2 | H35: Kg | I35: 7750 | J35: =G35*I35 -> 15500
C36: 4. Biaya Perbaikan | D36: = | E36: 10 % ( A / (a x b ) | J36: =0.1*((I15/(H13*H14))) -> 6000
J37: =SUM(J29:J36) -> 158141.75
C38: b. Indirect Cost ( Biaya Tak Langsung ) perjam
C39: (Biaya Gudang, Force Majeur, Over Head) = 10 % x Biaya Langsung | J39: =J37*0.1 -> 15814.175
D40: Total Biaya Peralatan Bor Perjam ....... | J40: =SUM(J37:J39) -> 173955.92
D41: Dibulatkan ............................. | J41: =ROUND(J40-5,-1) -> 173950
B44: B. | C44: PUMPING TEST EQUIPMENT
C46: Merk/Produksi | D46: : | E46: PENGGERAK DEUTZ, POMPA LOWARA
C47: Type/Model | D47: : | E47: SKID MOUNTED
C48: Umur Ekonomi | D48: : | E48: a..................... | H48: 3 | I48: tahun
C49: Jam Kerja Pertahun | D49: : | E49: b..................... | H49: 7500 | I49: jam
C50: Harga Dasar Alat | D50: : | E50: A..................... | I50: =50000000-5000000+1200000+2000000+800000 -> 49000000
C51: Nilai Depresiasi | D51: : | E51: B = A x 10 % ......... | I51: =I50*0.1 -> 4900000
...

Sheet BOR 6"
B3: NO | C3: U R A I A N | I3: HARGA SATUAN | J3: JUMLAH HARGA
I5: (Rp) | J5: (Rp)
B7: II. | C7: ANALISA PEKERJAAN PENGEBORAN
B9: A. | C9: DRILLING RIG
C11: Merk/Produksi | D11: : | E11: LONG YEARD 44 ( DRILLING RIG, PISTON PUMP )
C12: Type/Model | D12: : | E12: SKID MOUNTED
C13: Umur Ekonomi | D13: : | E13: a..................... | H13: 3 | I13: tahun
C14: Jam Kerja Pertahun | D14: : | E14: b..................... | H14: 2500 | I14: jam
C15: Harga Dasar Alat | D15: : | E15: A..................... | I15: 250000000 | K15: =[37]HARSAT!G35 -> 743325.29
C16: Nilai Depresiasi | D16: : | E16: B = A x 10 % ......... | I16: =I15*0.1 -> 25000000
C17: Nilai Sisa | D17: : | E17: C = A - B ............ | I17: =I15-I16 -> 225000000
C18: Data-Data Peralatan : | D18: :
C19: - HP/Berat | D19: : | E19: =100/2 -> 50 | F19: PK
C20: - Oli Mesin | D20: : | E20: =10/2 -> 5 | F20: Liter
C21: - Oli Gardan | D21: : | E21: =20/2 -> 10 | F21: Liter
C22: - Oli Transmisi | D22: : | E22: =20/2 -> 10 | F22: Liter
C23: - Oli Hidrolik | D23: : | E23: =90/2 -> 45 | F23: Liter
C25: Biaya Peralatan | D25: :
C26: a. Direct Cost ( Biaya Langsung ) perjam
C28: 1. Depresiasi
C29: 2. Biaya pemilikan, Asuransi, Pajak dll. = C : (a x b) | J29: =I17/(H13*H14) -> 30000
C30: 3. Biaya operasi peralatan perjam = 25 % x (a+1) : 2a x (A:b) | J30: =(((0.25*(H13+1))/(2*H13)))*(I15/H14) -> 16666.667
C31: a. Bahan Bakar | D31: = | E31: 0.15 | F31: x | G31: =E19 -> 50 | H31: Ltr | I31: 6800 | J31: =E31*G31*I31 -> 51000 | K31: 0.15
C32: b. Pelumas Mesin | D32: = | E32: =E20/200 -> 0.025 | F32: x | G32: =E19/G31 -> 1 | H32: Ltr | I32: 9750 | J32: =E32*G32*I32 -> 243.75 | K32: 10 | L32: / | M32: 200
C33: c. Pelumas Gardan | D33: = | E33: =E21/250 -> 0.04 | F33: x | G33: 1.2 | H33: Ltr | I33: 9750 | J33: =E33*G33*I33 -> 468 | K33: 20 | L33: / | M33: 250
C34: d. Pelumas Hidrolik | D34: = | E34: =E23/450 -> 0.1 | F34: x | G34: 1.2 | H34: Ltr | I34: 7750 | J34: =E34*G34*I34 -> 930 | K34: 90 | L34: / | M34: 450
C35: e. Stemfet/Graese | D35: = | G35: 2 | H35: Kg | I35: 7750 | J35: =G35*I35 -> 15500
C36: 4. Biaya Perbaikan | D36: = | E36: 10 % ( A / (a x b ) | J36: =0.1*((I15/(H13*H14))) -> 3333.3333
J37: =SUM(J29:J36) -> 118141.75
C38: b. Indirect Cost ( Biaya Tak Langsung ) perjam
C39: (Biaya Gudang, Force Majeur, Over Head) = 10 % x Biaya Langsung | J39: =J37*0.1 -> 11814.175
D40: Total Biaya Peralatan Bor Perjam ....... | J40: =SUM(J37:J39) -> 129955.92
D41: Dibulatkan ............................. | J41: =ROUND(J40-5,-1) -> 129950
B44: B. | C44: PUMPING TEST EQUIPMENT
C46: Merk/Produksi | D46: : | E46: PENGGERAK DEUTZ, POMPA LOWARA
C47: Type/Model | D47: : | E47: SKID MOUNTED
C48: Umur Ekonomi | D48: : | E48: a..................... | H48: 3 | I48: tahun
C49: Jam Kerja Pertahun | D49: : | E49: b..................... | H49: 7500 | I49: jam
C50: Harga Dasar Alat | D50: : | E50: A..................... | I50: =50000000-5000000+1200000+2000000+800000 -> 49000000
C51: Nilai Depresiasi | D51: : | E51: B = A x 10 % ......... | I51: =I50*0.1 -> 4900000
...

Sheet BOR 4"
B3: NO | C3: U R A I A N | I3: HARGA SATUAN | J3: JUMLAH HARGA
I5: (Rp) | J5: (Rp)
B7: II. | C7: ANALISA PEKERJAAN PENGEBORAN
B9: A. | C9: DRILLING RIG
C11: Merk/Produksi | D11: : | E11: LONG YEARD 44 ( DRILLING RIG, PISTON PUMP )
C12: Type/Model | D12: : | E12: SKID MOUNTED
C13: Umur Ekonomi | D13: : | E13: a..................... | H13: 3 | I13: tahun
C14: Jam Kerja Pertahun | D14: : | E14: b..................... | H14: 2500 | I14: jam
C15: Harga Dasar Alat | D15: : | E15: A..................... | I15: 150000000 | K15: 150000000
C16: Nilai Depresiasi | D16: : | E16: B = A x 10 % ......... | I16: 15000000 | K16: 15000000
C17: Nilai Sisa | D17: : | E17: C = A - B ............ | I17: 135000000 | K17: 135000000
C18: Data-Data Peralatan : | D18: :
C19: - HP/Berat | D19: : | E19: =100/4 -> 25 | F19: PK
C20: - Oli Mesin | D20: : | E20: =10/4 -> 2.5 | F20: Liter
C21: - Oli Gardan | D21: : | E21: =20/4 -> 5 | F21: Liter
C22: - Oli Transmisi | D22: : | E22: =20/4 -> 5 | F22: Liter
C23: - Oli Hidrolik | D23: : | E23: =90/4 -> 22.5 | F23: Liter
C25: Biaya Peralatan | D25: :
C26: a. Direct Cost ( Biaya Langsung ) perjam
C28: 1. Depresiasi
C29: 2. Biaya pemilikan, Asuransi, Pajak dll. = C : (a x b) | J29: =I17/(H13*H14) -> 18000
C30: 3. Biaya operasi peralatan perjam = 25 % x (a+1) : 2a x (A:b) | J30: =(((0.25*(H13+1))/(2*H13)))*(I15/H14) -> 10000
C31: a. Bahan Bakar | D31: = | E31: 0.15 | F31: x | G31: =E19 -> 25 | H31: Ltr | I31: 6800 | J31: =E31*G31*I31 -> 25500 | K31: 0.15
C32: b. Pelumas Mesin | D32: = | E32: =E20/200 -> 0.0125 | F32: x | G32: =E19/G31 -> 1 | H32: Ltr | I32: =10000-3000+1500+1000+250 -> 9750 | J32: =E32*G32*I32 -> 121.875 | K32: 10 | L32: / | M32: 200
C33: c. Pelumas Gardan | D33: = | E33: =E21/250 -> 0.02 | F33: x | G33: 1.2 | H33: Ltr | I33: =I32 -> 9750 | J33: =E33*G33*I33 -> 234 | K33: 20 | L33: / | M33: 250
C34: d. Pelumas Hidrolik | D34: = | E34: =E23/450 -> 0.05 | F34: x | G34: 1.2 | H34: Ltr | I34: =8000-2500+1300+700+250 -> 7750 | J34: =E34*G34*I34 -> 465 | K34: 90 | L34: / | M34: 450
C35: e. Stemfet/Graese | D35: = | G35: 2 | H35: Kg | I35: =I34 -> 7750 | J35: =G35*I35 -> 15500
C36: 4. Biaya Perbaikan | D36: = | E36: 10 % ( A / (a x b ) | J36: =0.1*((I15/(H13*H14))) -> 2000
J37: =SUM(J29:J36) -> 71820.875
C38: b. Indirect Cost ( Biaya Tak Langsung ) perjam
C39: (Biaya Gudang, Force Majeur, Over Head) = 10 % x Biaya Langsung | J39: =J37*0.1 -> 7182.0875
D40: Total Biaya Peralatan Bor Perjam ....... | J40: =SUM(J37:J39) -> 79002.962
D41: Dibulatkan ............................. | J41: =ROUND(J40-5,-1) -> 79000
B44: B. | C44: PUMPING TEST EQUIPMENT
C46: Merk/Produksi | D46: : | E46: PENGGERAK DEUTZ, POMPA LOWARA
C47: Type/Model | D47: : | E47: SKID MOUNTED
C48: Umur Ekonomi | D48: : | E48: a..................... | H48: 3 | I48: tahun
C49: Jam Kerja Pertahun | D49: : | E49: b..................... | H49: 7500 | I49: jam
C50: Harga Dasar Alat | D50: : | E50: A..................... | I50: =50000000-5000000+1200000+2000000+800000 -> 49000000 | K50: 49000000
C51: Nilai Depresiasi | D51: : | E51: B = A x 10 % ......... | I51: =I50*0.1 -> 4900000 | K51: 4900000
...

Sheet BOR 3"
B3: NO | C3: U R A I A N | I3: HARGA SATUAN | J3: JUMLAH HARGA
I5: (Rp) | J5: (Rp)
B7: II. | C7: ANALISA PEKERJAAN PENGEBORAN
B9: A. | C9: DRILLING RIG
C11: Merk/Produksi | D11: : | E11: Rakitan
C12: Type/Model | D12: : | E12: =E11 -> Rakitan
C13: Umur Ekonomi | D13: : | E13: a..................... | H13: 3 | I13: tahun
C14: Jam Kerja Pertahun | D14: : | E14: b..................... | H14: 2500 | I14: jam
C15: Harga Dasar Alat | D15: : | E15: A..................... | I15: 40000000
C16: Nilai Depresiasi | D16: : | E16: B = A x 10 % ......... | I16: =I15*0.1 -> 4000000
C17: Nilai Sisa | D17: : | E17: C = A - B ............ | I17: =I15-I16 -> 36000000
C18: Data-Data Peralatan : | D18: :
C19: - HP/Berat | D19: : | E19: =100/5 -> 20 | F19: PK
C20: - Oli Mesin | D20: : | E20: =10/5 -> 2 | F20: Liter
C21: - Oli Gardan | D21: : | E21: =20/5 -> 4 | F21: Liter
C22: - Oli Transmisi | D22: : | E22: =20/5 -> 4 | F22: Liter
C23: - Oli Hidrolik | D23: : | E23: =90/5 -> 18 | F23: Liter
C25: Biaya Peralatan | D25: :
C26: a. Direct Cost ( Biaya Langsung ) perjam
C28: 1. Depresiasi
C29: 2. Biaya pemilikan, Asuransi, Pajak dll. = C : (a x b) | J29: =I17/(H13*H14) -> 4800
C30: 3. Biaya operasi peralatan perjam = 25 % x (a+1) : 2a x (A:b) | J30: =(((0.25*(H13+1))/(2*H13)))*(I15/H14) -> 2666.6667
C31: a. Bahan Bakar | D31: = | E31: 0.15 | F31: x | G31: =E19 -> 20 | H31: Ltr | I31: 6800 | J31: =E31*G31*I31 -> 20400 | K31: 0.15
C32: b. Pelumas Mesin | D32: = | E32: =E20/200 -> 0.01 | F32: x | G32: =E19/G31 -> 1 | H32: Ltr | I32: =10000-3000+1500+1000+250 -> 9750 | J32: =E32*G32*I32 -> 97.5 | K32: 10 | L32: / | M32: 200
C33: c. Pelumas Gardan | D33: = | E33: =E21/250 -> 0.016 | F33: x | G33: 1.2 | H33: Ltr | I33: =I32 -> 9750 | J33: =E33*G33*I33 -> 187.2 | K33: 20 | L33: / | M33: 250
C34: d. Pelumas Hidrolik | D34: = | E34: =E23/450 -> 0.04 | F34: x | G34: 1.2 | H34: Ltr | I34: =8000-2500+1300+700+250 -> 7750 | J34: =E34*G34*I34 -> 372 | K34: 90 | L34: / | M34: 450
C35: e. Stemfet/Graese | D35: = | G35: 2 | H35: Kg | I35: =I34 -> 7750 | J35: =G35*I35 -> 15500
C36: 4. Biaya Perbaikan | D36: = | E36: 10 % ( A / (a x b ) | J36: =0.1*((I15/(H13*H14))) -> 533.33333
J37: =SUM(J29:J36) -> 44556.7
C38: b. Indirect Cost ( Biaya Tak Langsung ) perjam
C39: (Biaya Gudang, Force Majeur, Over Head) = 10 % x Biaya Langsung | J39: =J37*0.1 -> 4455.67
D40: Total Biaya Peralatan Bor Perjam ....... | J40: =SUM(J37:J39) -> 49012.37
D41: Dibulatkan ............................. | J41: =ROUND(J40-5,-1) -> 49010
B44: B. | C44: PUMPING TEST EQUIPMENT
C46: Merk/Produksi | D46: : | E46: PENGGERAK DEUTZ, POMPA LOWARA
C47: Type/Model | D47: : | E47: SKID MOUNTED
C48: Umur Ekonomi | D48: : | E48: a..................... | H48: 3 | I48: tahun
C49: Jam Kerja Pertahun | D49: : | E49: b..................... | H49: 7500 | I49: jam
C50: Harga Dasar Alat | D50: : | E50: A..................... | I50: =50000000-5000000+1200000+2000000+800000 -> 49000000 | K50: 49000000
C51: Nilai Depresiasi | D51: : | E51: B = A x 10 % ......... | I51: =I50*0.1 -> 4900000 | K51: 4900000
...
