Workbook
Name \F: #REF!
Name \F: #REF!
Name \I: #REF!
Name \I: #REF!
Name \p: #REF!
Name _______DIV1: #REF!
Name _______DIV1: #REF!
Name _______DIV10: #REF!
Name _______DIV10: #REF!
Name _______DIV11: #REF!
Name _______DIV11: #REF!
Name _______DIV2: #REF!
Name _______DIV2: #REF!
Name _______DIV3: #REF!
Name _______DIV3: #REF!
Name _______DIV4: #REF!
Name _______DIV4: #REF!
Name _______DIV5: #REF!
Name _______DIV5: #REF!
Name _______DIV6: #REF!
Name _______DIV6: #REF!
Name _______DIV7: #REF!
Name _______DIV7: #REF!
Name _______DIV8: #REF!
Name _______DIV8: #REF!
Name _______DIV9: #REF!
Name _______DIV9: #REF!
Name _______HAL1: #REF!
Name _______HAL1: #REF!
Name _______HAL2: #REF!
Name _______HAL2: #REF!
Name _______HAL3: #REF!
Name _______HAL3: #REF!
Name _______HAL4: #REF!
Name _______HAL4: #REF!
Name _______HAL5: #REF!
Name _______HAL5: #REF!
Name _______HAL6: #REF!
Name _______HAL6: #REF!
Name _______HAL7: #REF!
Name _______HAL7: #REF!
Name _______HAL8: #REF!
Name _______HAL8: #REF!
Name ______DIV1: #REF!
Name ______DIV1: #REF!
Name ______DIV10: #REF!
Name ______DIV10: #REF!
Name ______DIV11: #REF!
Name ______DIV11: #REF!
Name ______DIV2: #REF!
Name ______DIV2: #REF!
Name ______DIV3: #REF!
Name ______DIV3: #REF!
Name ______DIV4: #REF!
Name ______DIV4: #REF!
Name ______DIV5: #REF!
Name ______DIV5: #REF!
Name ______DIV6: #REF!
Name ______DIV6: #REF!
Name ______DIV7: #REF!

Sheet TABEL BESI
A1: 1. Tabel Berat Besi Baja H Beam
A3: No | B3: UKURAN (mm) | C3: PANJANG (M) | D3: Weight (Kg) | E3: BERAT /M1 (Kg)
A4: 1 | B4: L 100x100x6x8 | C4: 12 | D4: 206 | E4: 17167
A5: 2 | B5: L 125x125x5x7 | C5: 12 | D5: 222 | E5: 18500
A6: 3 | B6: L 125x125x6.5×9 | C6: 12 | D6: 286 | E6: 23833
A7: 4 | B7: L 150x150x7x10 | C7: 12 | D7: 378 | E7: 31500
A8: 5 | B8: L 175x175x7x11 | C8: 12 | D8: 482 | E8: 40167
A9: 6 | B9: L 200x200x8x12 | C9: 12 | D9: 599 | E9: 49917
A10: 7 | B10: L 250x250x9x14 | C10: 12 | D10: 869 | E10: 72417
A11: 8 | B11: L 300x300x10x15 | C11: 12 | D11: 1128 | E11: 94000
A12: 9 | B12: L 250x350x12x19 | C12: 12 | D12: 1644 | E12: 137000
A13: 10 | B13: L 400x400x13x21 | C13: 12 | D13: 2064 | E13: 172000
A15: Cara membaca tabel berat besi baja H Beam diatas adalah:
A17: Sebagai Contoh : L 100X100X6X8mm-12 M’ 206 kg 17.167
A19: Arti dimensi besi H beam tersebut adalah :
A21: Panjang 12 M
A23: Tinggi 10 cm
A25: Lebar 10 cm
A27: Tebal Badan 6 mm
A29: Tebal sayap 8 mm
A31: Mempunyai berat total 206 kg
A33: Sedangkan berat per M : 206 / 12 = 17.167
A37: 2. Tabel Berat Besi Baja WF ( Wide Flange )
A39: NO | B39: UKURAN (mm) | C39: PANJANG (M) | D39: Weight (Kg) | E39: BERAT /M1 (Kg)
A40: 1 | B40: WF 100X50X5 X7 | C40: 12 | D40: 112 | E40: 9333
A41: 2 | B41: WF 125X60X6 X8 | C41: 12 | D41: 158 | E41: 13200
A42: 3 | B42: WF 148X100X6X9 | C42: 12 | D42: 253 | E42: 21100
A43: 4 | B43: WF 150X75X5X7 | C43: 12 | D43: 168 | E43: 14000
A44: 5 | B44: WF 175X90X5X8 | C44: 12 | D44: 217 | E44: 18100
A45: 6 | B45: WF 198X99X4,5X7 | C45: 12 | D45: 218 | E45: 18200
A46: 7 | B46: WF 200X100X3,2X4,5 | C46: 12 | D46: 143 | E46: 11917
A47: 8 | B47: WF 200X100X5,5X8 | C47: 12 | D47: 256 | E47: 21333
A48: 9 | B48: WF 248X124X5X8 | C48: 12 | D48: 308 | E48: 25700
A49: 10 | B49: WF 250X125X6X9 | C49: 12 | D49: 355 | E49: 29600
A50: 11 | B50: WF 298X149X6X8 | C50: 12 | D50: 384 | E50: 32000
A51: 12 | B51: WF 300X150X6,5X9 | C51: 12 | D51: 440 | E51: 36700
... A62: 23 | B62: WF 800X300X14X26 | C62: 12 | D62: 2520 | E62: 210000
A64: Cara membaca tabel berat besi baja WF ( Wide Flange) diatas adalah :
A66: Sebagai Contoh : WF 100x50x5x7mm-12 M’ 112 kg 9.333
A68: Artinya dimensi besi WF tersebut adalah :
...

Sheet Perhitungan Volume
A1: PERHITUNGAN VOLUME PEKERJAAN
A4: DESA | C4: : Sukaluyu | I4: Lokasi : | J4: Kp. Tegalonyam
A5: KECAMATAN | C5: : Cijati | I5: Kegiatan : | J5: Pembangunan Rehabilitasi MCK
A6: KABUPATEN | C6: : Cianjur | I6: Volume : | J6: 1 Unit ( 2.5 x 3 ) m
A7: PROVINSI | C7: : Jawa Barat
A11: No. | B11: Jenis Pekerjaan | C11: Sat. | D11: Sketsa | F11: VOLUME
F12: P | H12: L | J12: T | L12: Jml | N12: volume
Q13: =#REF!*1.2 -> #REF!
A15: A | B15: PEKERJAAN PERSIAPAN
A16: 1 | B16: Pek. Pasang bouwplank | C16: M' | F16: 6 | G16: + | H16: 2 | I16: + | M16: = | N16: =F16+H16+J16 -> 8
A17: 2 | B17: Pembersihan Lahan sebelum dan sesudah pembangunan | C17: M2 | F17: 6 | G17: X | H17: 2 | M17: = | N17: =F17*H17 -> 12
A19: B | B19: PEKERJAAN TANAH
A20: 1 | B20: Galian tanah pondasi batu kali dan sloof | C20: M3 | F20: =2+2+6+6 -> 16 | G20: x | H20: 0.5 | I20: x | J20: 0.4 | M20: = | N20: =F20*H20*J20 -> 3.2
A21: 2 | B21: Urugan pasir bawah pondasi t = 3 cm | C21: M3 | F21: =F20 -> 16 | G21: =G20 -> x | H21: 0.5 | I21: =I20 -> x | J21: 0.05 | M21: = | N21: =F21*H21*J21 -> 0.4 | Q21: =1.5*3.15 -> 4.725
A22: 3 | B22: Urugan tanah kembali | C22: M3 | M22: = | N22: =N21*0.25 -> 0.1 | Q22: =Q21/2 -> 2.3625
A24: C | B24: PEKERJAAN PASANGAN | Q24: =0.7*2.4 -> 1.68
A25: 1 | B25: Pondasi batu kali Menerus Campuran 1 PC : 4 PP | C25: M3 | F25: =F20 -> 16 | G25: x | H25: =(0.25+0.5)/2 -> 0.375 | K25: * | L25: 0.5 | M25: = | N25: =F25*H25*L25 -> 3 | Q25: =Q24*2 -> 3.36
A26: =A25+1 -> 2 | B26: Pas. dinding Bata Ringan | C26: M2 | F26: =F25 -> 16 | I26: x | J26: 3.05 | K26: - | L26: =Q25 -> 3.36 | M26: = | N26: =((F26*J26)-L26) -> 45.44 | Q26: =Q25-Q22 -> 0.9975
A27: 2 | B27: Pas. dinding batu tempel | C27: M2 | F27: 10 | I27: x | J27: 0.8 | M27: = | N27: =F27*J27 -> 8
F28: =+F27 -> 10 | I28: x | J28: 3.05 | K28: - | L28: =+L26 -> 3.36 | M28: = | N28: =(F28*J28)-L28 -> 27.14
A29: =A27+1 -> 3 | B29: Plesteran dinding 1pc ; 4ps | C29: =C27 -> M2 | M29: = | N29: =+N28*2 -> 54.28
A30: 3 | B30: Pek. Acian | M30: = | N30: =N29 -> 54.28
A32: D | B32: PEKERJAAN BETON
A33: 1 | B33: Sloof Beton Uk.15/20, ad. 1:2:3 | C33: m3 | F33: =F25 -> 16 | G33: x | H33: 0.2 | I33: x | J33: 0.15 | M33: = | N33: =J33*H33*F33 -> 0.48
B34: Tulangan besi polos Ф 12 mm | C34: m' | F34: =F33 -> 16 | G34: x | H34: 4 | M34: = | N34: =F34*4 -> 64 | P34: =N34*0.888 -> 56.832
B35: Jumlah total besi Ф 12 mm | C35: btg | F35: 12 | M35: = | N35: =N34/F35 -> 5.3333333 | P35: =0.888 -> 0.888 | Q35: =P35*F35 -> 10.656
B36: berat per batang = 10.68 | C36: kg | N36: =N35*10.656 -> 56.832 | P36: Ring Balk | Q36: 28 | R36: =0.4+0.4+0.15 -> 0.95
R37: =Q36*R36 -> 26.6
B38: Tulangan geser Ф 8 mm | C38: m' | F38: 2 | G38: x | H38: 0.15 | I38: ,+ | J38: 0.1 | K38: ,+ | L38: 0.05 | N38: =F38*(H38+J38)+L38 -> 0.55
B39: jarak per 15 cm (7 bh/m') | C39: m' | F39: =F33*7 -> 112 | M39: = | N39: =N38*F39 -> 61.6
B40: Jumlah total besi Ф 8 mm | C40: btg | F40: 12 | M40: = | N40: =N39/F40 -> 5.1333333
B41: berat per batang = 4.74 | C41: kg | M41: = | N41: =N40*4.74 -> 24.332 | P41: 0.395 | Q41: =P41*12 -> 4.74
B42: TOTAL PEMBESIAN KG/M3 | C42: Kg/m3 | N42: =N41+N36 -> 81.164
B44: Bekisting Sloof | F44: =F33 -> 16 | G44: x | H44: 0.2 | K44: x | L44: 2 | N44: =+F44*H44*L44 -> 6.4
A46: 2 | B46: Kolom Praktis uk. 15 x 15 cm ad. 1:2:3 | C46: m3 | F46: =3*8 -> 24 | H46: 0.15 | J46: 0.15 | N46: =F46*H46*J46 -> 0.54
B47: Tulangan besi polos Ф 12 mm | C47: m' | F47: =F46 -> 24 | N47: =F46*4 -> 96
B48: Jumlah total besi Ф 12 mm | C48: btg | F48: 12 | N48: =N47/F48 -> 8
B49: berat per batang = 10.68 | C49: kg | N49: =N48*10.656 -> 85.248
B51: Tulangan geser Ф 8 mm | C51: m'
B52: jarak per 15 cm (7 bh/m') | C52: m' | H52: 0.11 | J52: 0.11 | N52: =2*(H52+J52)+0.05 -> 0.49
...

Sheet Upah Bahan
D4: HARGA SATUAN UPAH - MATERIAL - ALAT
D6: NO | E6: Kode | F6: UPAH - MATERIAL - ALAT | G6: SATUAN | H6: HARGA SATUAN | I6: KETERANGAN | K6: HARGA SATUAN
D7: 1 | F7: 2 | G7: 3 | H7: 4 | I7: 5 | K7: 4
D8: I. | E8: UPAH
D9: 1 | E9: L.01 | F9: Pekerja | G9: OH | H9: 100000 | K9: 100000
D10: 1 | E10: L.02 | F10: Tukang batu | G10: OH | H10: 135000 | K10: 145000
D11: 3 | E11: L.02 | F11: Tukang kayu | G11: OH | H11: 135000 | K11: 145000
D12: 3 | E12: L.02 | F12: Tukang besi | G12: OH | H12: 135000 | K12: 145000
D13: 3 | E13: L.02 | F13: Tukang cat | G13: OH | H13: 135000 | K13: 145000
D14: 6 | E14: L.02 | F14: Tukang pelitur | G14: OH | H14: 145000 | K14: 145000
D15: 7 | E15: L.02 | F15: Tukang pipa | G15: OH | H15: 135000 | K15: 145000
D16: 8 | E16: L.02 | F16: Tukang penganyam bronjong | G16: OH | H16: 145000 | K16: 145000
D17: 9 | E17: L.02 | F17: Tukang tebas | G17: OH | H17: 145000 | K17: 145000
D18: 10 | E18: L.02 | F18: Tukang las | G18: OH | H18: 145000 | K18: 145000
D19: 11 | E19: L.02 | F19: Tukang las geotextile | G19: OH | H19: 145000 | K19: 145000
D20: 3 | E20: L.02 | F20: Tukang listrik | G20: OH | H20: 135000 | K20: 145000
D21: 13 | E21: L.02 | F21: Tukang alumunium | G21: OH | H21: 145000 | K21: 145000
D22: 14 | E22: L.02 | F22: Tukang kaca | G22: OH
D23: 15 | E23: L.02 | F23: Tukang erection | G23: OH | H23: 145000 | K23: 145000
D24: 16 | E24: L.02 | F24: Tukang tanam | G24: OH | H24: 145000 | K24: 145000
D25: 17 | F25: Tukang Tanam | G25: OH | H25: =125%*145000 -> 181250 | K25: =125%*145000 -> 181250
D26: 18 | F26: Kepala Tukang Tanam | G26: OH | H26: =125%*175000 -> 218750 | K26: =125%*175000 -> 218750
D27: 19 | F27: Tukang pemelihara taman | G27: OH | H27: 145000 | K27: 145000
D28: 20 | F28: Tukang pemelihara taman (115% Pekerja) | G28: OH | H28: =115%*H9 -> 115000 | K28: =115%*K9 -> 115000
D29: 21 | F29: Tukang gali | G29: OH | H29: 120000 | K29: 120000
D30: 22 | F30: Tukang aspal | G30: OH | H30: 120000 | K30: 120000
D31: 1 | E31: L.03 | F31: Kepala tukang | G31: OH | H31: 150000 | K31: 175000
D32: 1 | E32: L.04 | F32: Mandor | G32: OH | H32: 160000 | K32: 200000
D33: 25 | E33: L.05 | F33: Juru ukur | G33: OH | H33: 175000 | K33: 175000
D34: 26 | E34: L.06 | F34: Pembantu juru ukur | G34: OH | H34: 150000 | K34: 150000
D35: 27 | E35: L.07 | F35: Mekanik alat berat | G35: OH | H35: 220000 | K35: 220000
D36: 28 | E36: L.08 | F36: Operator alat berat | G36: OH | H36: 250000 | K36: 250000
D37: 29 | E37: L.09 | F37: Pembantu operator alat berat | G37: OH | H37: 130000 | K37: 130000
D38: 30 | E38: L.10 | F38: Sopir | G38: OH | H38: 200000 | K38: 200000
D39: 31 | E39: L.11 | F39: Kenek | G39: OH | H39: 135000 | K39: 135000
D40: 32 | F40: Administrasi bor | G40: OH | H40: 110000 | K40: 110000
D41: 33 | F41: Ahli geologist | G41: OH | H41: 400000 | K41: 400000
D42: 34 | F42: Ahli topografi | G42: OH | H42: 400000 | K42: 400000
D43: 35 | F43: Crew driller | G43: OH | H43: 125000 | K43: 125000
D44: 36 | F44: Driller | G44: OH | H44: 140000 | K44: 140000
...

Sheet AHSP MCK
C4: Keuntungan | D4: 0.1
C5: 1.1.2.4 | D5: Pembuatan 1 m2 direksi keet (Kantor), los kerja dan gudang | K5: =ROUNDDOWN(J30,-2) -> 2089800 | L5: tidak ada perbahan | M5: Revisi
C6: No | D6: Uraian | F6: Sat. | G6: Koefisien | H6: Harga Satuan (Rp) | J6: Jumlah Harga (Rp)
C7: A | D7: TENAGA KERJA
C8: 1 | D8: Pekerja | E8: L.01 | F8: OH | G8: 1.2 | H8: =VLOOKUP(D8,upahbahan,3,FALSE) -> 100000 | J8: =G8*H8 -> 120000
C9: 2 | D9: Tukang batu | E9: L.02 | F9: OH | G9: 0.4 | H9: =VLOOKUP(D9,upahbahan,3,FALSE) -> 135000 | J9: =G9*H9 -> 54000
C10: 3 | D10: Kepala tukang | E10: L.03 | F10: OH | G10: 0.04 | H10: =VLOOKUP(D10,upahbahan,3,FALSE) -> 150000 | J10: =G10*H10 -> 6000
C11: 4 | D11: Mandor | E11: L.04 | F11: OH | G11: 0.12 | H11: =VLOOKUP(D11,upahbahan,3,FALSE) -> 160000 | J11: =G11*H11 -> 19200
C12: JUMLAH HARGA TENAGA KERJA | J12: =SUM(J8:J11) -> 199200
C13: B | D13: BAHAN
C14: 1 | D14: Kaso 5/7 | F14: m3 | G14: 0.35 | H14: =VLOOKUP(D14,upahbahan,3,FALSE) -> 2250000 | J14: =G14*H14 -> 787500
C15: 2 | D15: Multiplek tebal 4 mm | F15: lembar | G15: 1 | H15: =VLOOKUP(D15,upahbahan,3,FALSE) -> 64620 | J15: =G15*H15 -> 64620
C16: 3 | D16: Fondasi pasangan batu | F16: m3 | G16: 0.17 | H16: =VLOOKUP(D16,upahbahan,3,FALSE) -> 322875 | J16: =G16*H16 -> 54888.75
C17: 4 | D17: GRC Pelat t=4 mm uk 122x244 cm | F17: lembar | G17: 1.24 | H17: =VLOOKUP(D17,upahbahan,3,FALSE) -> 72000 | J17: =G17*H17 -> 89280
C18: 5 | D18: Paku | F18: kg | G18: 0.75 | H18: =VLOOKUP(D18,upahbahan,3,FALSE) -> 33075 | J18: =G18*H18 -> 24806.25
C19: 6 | D19: Asbes gelombang | F19: lembar | G19: 0.3 | H19: =VLOOKUP(D19,upahbahan,3,FALSE) -> 101475 | J19: =G19*H19 -> 30442.5
C20: 7 | D20: Paku asbes | F20: kg | G20: 0.1 | H20: ='Upah Bahan'!H1023 -> 33075 | J20: =G20*H20 -> 3307.5
C21: 8 | D21: Floor lantai (Beton lantai kerja) | F21: m3 | G21: 0.15 | H21: =VLOOKUP(D21,upahbahan,3,FALSE) -> 805600 | J21: =G21*H21 -> 120840
C22: 9 | D22: Pintu Double teakwood rangka kayu | F22: m2 | G22: 0.1 | H22: =VLOOKUP(D22,upahbahan,3,FALSE) -> 765000 | J22: =G22*H22 -> 76500
C23: 10 | D23: Frame besi kaca nako | F23: daun | G23: 1 | H23: =VLOOKUP(D23,upahbahan,3,FALSE) -> 36000 | J23: =G23*H23 -> 36000
C24: 11 | D24: cat dinding | F24: m2 | G24: 16.5 | H24: =VLOOKUP(D24,upahbahan,3,FALSE) -> 25000 | J24: =G24*H24 -> 412500
C25: JUMLAH HARGA BAHAN | J25: =SUM(J14:J24) -> 1700685
C26: C | D26: PERALATAN
C27: JUMLAH HARGA ALAT | J27: 0
C28: D | D28: Jumlah (A+B+C) | J28: =J12+J25+J27 -> 1899885
C29: E | D29: Biaya Umum dan Keuntungan 10%-15% x D | H29: =$D$4 -> 0.1 | J29: =J28*H29 -> 189988.5
C30: F | D30: Harga Satuan Pekerjaan (D+E) | J30: =SUM(J28:J29) -> 2089873.5
C32: 1.1.4.2 | D32: Pasangan 1 m' bouwplank | K32: =ROUNDDOWN(J50,-2) -> 74500 | L32: - | M32: -
C33: No | D33: Uraian | E33: Kode | F33: Sat. | G33: Koefisien | H33: Harga Satuan (Rp) | J33: Jumlah Harga (Rp)
C34: A | D34: TENAGA KERJA
C35: 1 | D35: Pekerja | E35: L.01 | F35: OH | G35: 0.012 | H35: =VLOOKUP(D35,upahbahan,3,FALSE) -> 100000 | J35: =G35*H35 -> 1200
C36: 2 | D36: Tukang kayu | E36: L.02 | F36: OH | G36: 0.006 | H36: =VLOOKUP(D36,upahbahan,3,FALSE) -> 135000 | J36: =G36*H36 -> 810
C37: 3 | D37: Kepala tukang | E37: L.03 | F37: OH | G37: 0.0006 | H37: =VLOOKUP(D37,upahbahan,3,FALSE) -> 150000 | J37: =G37*H37 -> 90
C38: 4 | D38: Mandor | E38: L.04 | F38: OH | G38: 0.0012 | H38: =VLOOKUP(D38,upahbahan,3,FALSE) -> 160000 | J38: =G38*H38 -> 192
C39: JUMLAH HARGA TENAGA KERJA | J39: =SUM(J35:J38) -> 2292
C40: B | D40: BAHAN
C41: 1 | D41: Kaso 5/7 | F41: m3 | G41: 0.013 | H41: =VLOOKUP(D41,upahbahan,3,FALSE) -> 2250000 | J41: =G41*H41 -> 29250
C42: 2 | D42: Kayu papan 3/20 cm | F42: m3 | G42: 0.007 | H42: =VLOOKUP(D42,upahbahan,3,FALSE) -> 3150000 | J42: =G42*H42 -> 22050
C43: 3 | D43: Paku 2 inch | F43: kg | G43: 0.02 | H43: =VLOOKUP(D43,upahbahan,3,FALSE) -> 33901.875 | J43: =G43*H43 -> 678.0375
C44: JUMLAH HARGA BAHAN | J44: =SUM(J41:J43) -> 51978.037
...

Sheet SMKK
B2: SISTEM MANAJEMEN KESELAMATAN KONSTRUKSI (SMKK)
B4: Sumber : PERMEN PUPR No. 10 Tahun Tahun 2021 Tentang Pedoman Sistem Manajemen Keselamatan Konstruksi
B7: NO. | C7: URAIAN PEKERJAAN | F7: SATUAN PEMBAYARAN | G7: KUANTITAS | H7: HARGA SATUAN (RP.) | I7: TOTAL HARGA (RP.) | J7: KETERANGAN | L7: NILAI TKDN | M7: HARGA TKDN
B8: 1 | C8: 2 | F8: 3 | G8: 4 | H8: 5 | I8: 6 = 4 * 5 | J8: 7 | L8: 8 | M8: 9
B10: I. | C10: PENYIAPAN RKK:
C11: a. | D11: Pembuatan Dokumen Rencana Keselamatan Konstruksi | F11: Set | G11: 1 | H11: 200000 | I11: =G11*H11 -> 200000 | J11: Memperhatikan jumlah dan jenis pekerjaan yang dikerjakan | L11: 0 | M11: =H11*L11 -> 0
C12: b. | D12: Pembuatan Prosedur dan Instruksi Kerja | F12: Set
C13: c. | D13: Penyiapan Formulir | F13: Set
C14: A. | D14: Sub Total Penyiapan RKK | I14: =SUM(I11) -> 200000 | M14: =SUM(M11) -> 0
B16: II. | C16: SOSIALISASI, PROMOSI, DAN PELATIHAN:
C17: a. | D17: Induksi K3 (Safety Induction) | F17: Org | G17: 4 | H17: 10000 | I17: =G17*H17 -> 40000 | J17: Memperhatikan perkiraan jumlah pekerja, tamu, dan staf | L17: 0 | M17: =H17*L17 -> 0
C18: b. | D18: Pertemuan Keselamatan (Safety Talk dan / atau Tool Box Meeting) | F18: Org | G18: =G17 -> 4 | H18: 10000 | I18: =G18*H18 -> 40000 | J18: Memperhatikan perkiraan jumlah pekerja dan risiko k3 pekerjaan | L18: 0 | M18: =H18*L18 -> 0
C19: c | D19: Spanduk (banner) | F19: Lbr | H19: ='[45]HARGA BAHAN & ALAT'!$F$189 -> 135900 | I19: =G19*H19 -> 0 | J19: Memperhatikan lokasi pekerjaan dan waktu pekerjaan | L19: ='[45]HARGA BAHAN & ALAT'!H189 -> #REF! | M19: =H19*L19 -> #REF!
C20: d. | D20: Poster | F20: Lbr | H20: ='[45]HARGA BAHAN & ALAT'!$F$168 -> 14000 | I20: =G20*H20 -> 0 | J20: Memperhatikan lokasi pekerjaan dan waktu pekerjaan | L20: ='[45]HARGA BAHAN & ALAT'!H168 -> #REF! | M20: =H20*L20 -> #REF!
C21: e. | D21: Papan Informasi K3 | F21: Bh | G21: 0 | H21: ='[45]HARGA BAHAN & ALAT'!$F$169 -> 426000 | I21: =G21*H21 -> 0 | J21: Memperhatikan risiko k3 pekerjaan | L21: ='[45]HARGA BAHAN & ALAT'!J169 -> 0 | M21: =H21*L21 -> 0
C22: B. | D22: Sub Total Sosialisasi, Promosi dan Pelatihan | I22: =SUM(I17:I21) -> 80000 | M22: =SUM(M17:M21) -> #REF!
B24: III. | C24: ALAT PELINDUNG KERJA (APK) DAN ALAT PELINDUNG DIRI (APD):
C25: a. | D25: APK Antara Lain:
D26: 1 | E26: Pembatas Area (Restricted Area) / Safety Line | F26: Bh | H26: ='[45]HARGA BAHAN & ALAT'!F170 -> 34000 | I26: =G26*H26 -> 0 | J26: Sesuai kebutuhan | L26: ='[45]HARGA BAHAN & ALAT'!J170 -> 0 | M26: =H26*L26 -> 0
C27: b. | D27: APD Antara Lain:
D28: 1 | E28: Topi Pelindung (Safety Helmet) | F28: Bh | G28: =G18 -> 4 | H28: 25000 | I28: =G28*H28 -> 100000 | J28: Memperhatikan perkiraan jumlah pekerja tamu dan staf | L28: ='[45]HARGA BAHAN & ALAT'!H171 -> 0.7112 | M28: =H28*L28 -> 17780 | N28: https://tkdn.kemenperin.go.id/sertifikat_perush.php?id=LXgDzIgDALi1Ge2ukHE7ZXx53avqEQjgBFBeb1z21ps,&id_siinas=LXgDzIgDALi1Ge2ukHE7ZXx53avqEQjgBFBeb1z21ps,
D29: 2 | E29: Sarung Tangan (Safety Gloves) | F29: Psg | G29: =G28 -> 4 | H29: 10000 | I29: =G29*H29 -> 40000 | J29: Sesuai kebutuhan | L29: ='[45]HARGA BAHAN & ALAT'!H175 -> 0.3263 | M29: =H29*L29 -> 3263 | N29: https://tkdn.kemenperin.go.id/sertifikat_perush.php?id=w-Y65P5c9W2YTOjPtMbiggEIxZYqgOC_2uf6vZXvY1s,&id_siinas=vq2DN3VwRxHs25X0BxmbQiFY8n_irbYjEg-5_LMePFo,
D30: 3 | E30: Sepatu Keselamatan (Safety Shoes) | F30: Psg | G30: =G29 -> 4 | H30: 87500 | I30: =G30*H30 -> 350000 | J30: Memperhatikan perkiraan jumlah pekerja tamu dan staf | L30: ='[45]HARGA BAHAN & ALAT'!H176 -> 0.8695 | M30: =H30*L30 -> 76081.25 | N30: https://tkdn.kemenperin.go.id/sertifikat_perush.php?id=qlXiOPwQVC1Ugd23hMrAjlt4wrfHvpLDs0C4F-q3-1E,&id_siinas=ajfIiFxWAc5tzDubq0-dX0MfNpFQ5ktPydWY9IqmyXk,
D31: 4 | E31: Rompi Keselamatan (Safety Vest) | F31: Bh | G31: =G30 -> 4 | H31: 10000 | I31: =G31*H31 -> 40000 | J31: Sesuai kebutuhan | L31: ='[45]HARGA BAHAN & ALAT'!H188 -> 0.7122 | M31: =H31*L31 -> 7122 | N31: https://tkdn.kemenperin.go.id/sertifikat_perush.php?id=BwjfXmFNy_PcPmlGSjWRfwFf_0CbZkh4h9MFN_ZqS8A,&id_siinas=cKhWiTRLRcHuRXFwucFMztay0TF-lws89_R8XrROL5Y,
C32: C. | D32: Sub Total Alat Pelindung Kerja dan Alat Pelindung Diri | I32: =SUM(I25:I31) -> 530000
B34: IV. | C34: ASURANSI DAN PERIZINAN:
C35: a. | D35: Asuransi JKK dan JKM | F35: Ls | H35: 600000 | I35: =G35*H35 -> 0 | L35: ='[45]HARGA BAHAN & ALAT'!H187 -> #REF! | M35: =H35*L35 -> #REF!
C36: D. | D36: Sub Total Asuransi dan Perizinan | I36: =SUM(I35:I35) -> 0 | M36: =SUM(M35:M35) -> #REF!
B38: V. | C38: PERSONEL K3 KONSTRUKSI:
C39: E. | D39: Sub Total Personel K3 Konstruksi | M39: =SUM(#REF!) -> #REF!
B41: VI. | C41: FASILITAS, SARANA DAN PRASARANA KESEHATAN:
C42: a. | D42: Peralatan P3K Umum (Kotak P3K, Obat Luka, Perban,dll) | F42: Ls | G42: 1 | H42: 190000 | I42: =G42*H42 -> 190000 | J42: Memperhatikan perkiraan jumlah pekerja dan risiko k3 pekerjaan | L42: ='[45]HARGA BAHAN & ALAT'!H178 -> 0 | M42: =H42*L42 -> 0
C43: F. | D43: Sub Total Fasilitas, Sarana, dan Prasarana Kesehatan | I43: =SUM(I42:I42) -> 190000 | M43: =SUM(M42:M42) -> 0
B45: VII. | C45: RAMBU-RAMBU YANG DIPERLUKAN:
C46: a. | D46: Rambu Petunjuk | F46: Bh | H46: ='[45]HARGA BAHAN & ALAT'!$F$179 -> 133200 | I46: =G46*H46 -> 0 | J46: Sesuai kebutuhan | L46: ='[45]HARGA BAHAN & ALAT'!$H$179 -> 0.4102 | M46: =H46*L46 -> 54638.64 | N46: https://tkdn.kemenperin.go.id/sertifikat_perush.php?id=QSsoMNgrkDEYcCxSuXBQOYxgtTtMbAZEyUEZIjoHkeM,&id_siinas=e_LvgcF-xqow-MxHTRxjI-78147nnLCAUxKl7HxUfnc,
C47: b. | D47: Rambu Larangan | F47: Bh | H47: ='[45]HARGA BAHAN & ALAT'!$F$179 -> 133200 | I47: =G47*H47 -> 0 | J47: Sesuai kebutuhan | L47: ='[45]HARGA BAHAN & ALAT'!$H$179 -> 0.4102 | M47: =H47*L47 -> 54638.64 | N47: https://tkdn.kemenperin.go.id/sertifikat_perush.php?id=QSsoMNgrkDEYcCxSuXBQOYxgtTtMbAZEyUEZIjoHkeM,&id_siinas=e_LvgcF-xqow-MxHTRxjI-78147nnLCAUxKl7HxUfnc,
C48: c. | D48: Rambu Peringatan | F48: Bh | H48: ='[45]HARGA BAHAN & ALAT'!$F$179 -> 133200 | I48: =G48*H48 -> 0 | J48: Sesuai kebutuhan | L48: ='[45]HARGA BAHAN & ALAT'!$H$179 -> 0.4102 | M48: =H48*L48 -> 54638.64 | N48: https://tkdn.kemenperin.go.id/sertifikat_perush.php?id=QSsoMNgrkDEYcCxSuXBQOYxgtTtMbAZEyUEZIjoHkeM,&id_siinas=e_LvgcF-xqow-MxHTRxjI-78147nnLCAUxKl7HxUfnc,
C49: d. | D49: Rambu Kewajiban | F49: Bh | H49: ='[45]HARGA BAHAN & ALAT'!$F$179 -> 133200 | I49: =G49*H49 -> 0 | J49: Sesuai kebutuhan | L49: ='[45]HARGA BAHAN & ALAT'!$H$179 -> 0.4102 | M49: =H49*L49 -> 54638.64 | N49: https://tkdn.kemenperin.go.id/sertifikat_perush.php?id=QSsoMNgrkDEYcCxSuXBQOYxgtTtMbAZEyUEZIjoHkeM,&id_siinas=e_LvgcF-xqow-MxHTRxjI-78147nnLCAUxKl7HxUfnc,
C50: G. | D50: Sub Total Rambu-rambu yang Diperlukan | I50: =SUM(I46:I49) -> 0
B52: VIII. | C52: KONSULTASI DENGAN AHLI TERKAIT KESELAMATAN KONSTRUKSI:
...

Sheet Vol
A1: Perhitungan Tulangan
A2: Lantai
A3: Panjang | B3: 1.3 | C3: m
A4: Lebar | B4: 1.3 | C4: m
A5: Jarak | B5: 0.15 | C5: m
A7: Tul. Vertikal | B7: =B3/B5 -> 8.6666667 | C7: =ROUNDUP(B7,0) -> 9 | D7: meter
A8: Tul. Horizontal | B8: =B4/B5 -> 8.6666667 | C8: =ROUNDUP(B8,0) -> 9 | D8: meter
A10: Batang Vertikal | B10: =C7/E10 -> 0.75 | C10: batang | D10: 1 batang | E10: 12 | F10: meter
A11: Batang Horizontal | B11: =C8/E10 -> 0.75 | C11: batang | D11: Berat 1 batang | E11: 4.74 | F11: kg
A12: Total Batang | B12: =SUM(B10:B11) -> 1.5 | C12: batang
A13: Total Berat Lantai | B13: =B12*E11 -> 7.11 | C13: kg
A15: Dinding
A16: Panjang | B16: 1.3 | C16: m
A17: Lebar | B17: 1.5 | C17: m
A18: Jarak | B18: 0.15 | C18: m
A20: Tul. Vertikal | B20: =B16/B18 -> 8.6666667 | C20: =ROUNDUP(B20,0) -> 9 | D20: meter
A21: Tul. Horizontal | B21: =B17/B18 -> 10 | C21: =ROUNDUP(B21,0) -> 10 | D21: meter
A23: Batang Vertikal | B23: =C20/E23 -> 0.75 | C23: batang | D23: 1 batang | E23: 12 | F23: meter
A24: Batang Horizontal | B24: =C21/E23 -> 0.83333333 | C24: batang | D24: Berat 1 batang | E24: 4.74 | F24: kg
A25: Total Batang | B25: =SUM(B23:B24) -> 1.5833333 | C25: batang
A26: Total Berat Dinding | B26: =B25*E24 -> 7.505 | C26: kg | D26: =B26*4 -> 30.02
A28: Plat
A29: Panjang | B29: =4.65+2.65 -> 7.3 | C29: m
A30: Lebar | B30: =2+0.65 -> 2.65 | C30: m
A31: Jarak | B31: 0.15 | C31: m
A33: Tul. Vertikal | B33: =B29/B31 -> 48.666667 | C33: =ROUNDUP(B33,0) -> 49 | D33: meter
A34: Tul. Horizontal | B34: =B30/B31 -> 17.666667 | C34: =ROUNDUP(B34,0) -> 18 | D34: meter
A36: Batang Vertikal | B36: =C33/E36 -> 4.0833333 | C36: batang | D36: 1 batang | E36: 12 | F36: meter
A37: Batang Horizontal | B37: =C34/E36 -> 1.5 | C37: batang | D37: Berat 1 batang | E37: 4.74 | F37: kg
A38: Total Batang | B38: =SUM(B36:B37) -> 5.5833333 | C38: batang
A39: Total Berat plat | B39: =B38*E37 -> 26.465 | C39: kg
A41: Kawat Bendrat
A42: Berat Besi | B42: =(B39+D26+B13) -> 63.595 | C42: kg
A43: Koefisien | B43: 0.015
A44: Total | B44: =B43*B42 -> 0.953925 | C44: kg
A46: Sloof
A47: Panjang | B47: 2.6 | C47: m | D47: Panjang Sengkang | E47: 0.08
A48: Lebar | B48: 1.35 | C48: m | D48: Lebar Sengkang | E48: 0.13
A49: Jarak | B49: 0.15 | C49: m | D49: Bending | E49: 0.05
A51: Panjang total | B51: =(B47+B47+B48+B48+B48)*4 -> 37 | C51: m
...

Sheet Harsat MCK
B2: DAFTAR HARGA SATUAN PEKERJAAN (DHSP)
B3: BIDANG CIPTA KARYA
B4: Berdasarkan SE Bina Konstruksi Nomor 30/SE/Dk/2025
B6: KODE PRODUCT | C6: BIDANG | D6: URAIAN PEKERJAAN | E6: VOLUME | F6: HARGA SATUAN | G6: PAGU
G7: =SUM(G8:G55,G62:G76,G79:G91) -> 4230165.3 | H7: =(G7*11%)+G7 -> 4695483.5
B8: 1.1.2.4 | C8: BIDANG CIPTA KARYA | D8: Sewa Direksi Keet | E8: 1 | F8: 500000 | G8: =E8*F8 -> 500000
B9: 1.1.4.2 | C9: BIDANG UMUM | D9: Pasangan 1 m' bouwplank | E9: =(1.5*2)+(1.9*2) -> 6.8 | F9: =VLOOKUP(D9,'AHSP MCK'!D:K,8,FALSE) -> 74500 | G9: =E9*F9 -> 506600
B10: 1.2.1.1.1 | C10: BIDANG UMUM | D10: Penggalian 1 m3 tanah biasa sedalam 0 s.d. 1 m untuk volume s.d. 200 m3 secara manual | E10: =0.4*0.4*(1.5+1.5+1.9+1.9) -> 1.088 | F10: =VLOOKUP(D10,'AHSP MCK'!D:K,8,FALSE) -> 89100 | G10: =E10*F10 -> 96940.8
B11: 1.3.1.1 | C11: BIDANG UMUM | D11: 1 m3 urukan kembali galian tanah ( >0 s.d 200 m3) tanpa pemadatan secara manual | E11: =E10/4 -> 0.272 | F11: =VLOOKUP(D11,'AHSP MCK'!D:K,8,FALSE) -> 59400 | G11: =E11*F11 -> 16156.8
B12: 1.3.1.2 | C12: BIDANG UMUM | D12: 1 m3 urukan pasir uruk untuk volume s.d 200 m3 tanpa pemadatan secara manual | E12: 0.1 | F12: =VLOOKUP(D12,'AHSP MCK'!D:K,8,FALSE) -> 326700 | G12: =E12*F12 -> 32670
B13: 1.4.1.2 | C13: BIDANG UMUM | D13: Mengangkut 1 m3 tanah lepas, jarak angkut > 10 m s.d 20 m | E13: =E10-E11 -> 0.816 | F13: =VLOOKUP(D13,'AHSP MCK'!D:K,8,FALSE) -> 26700 | G13: =E13*F13 -> 21787.2
B14: 2.1.1.1 | C14: BIDANG CIPTA KARYA | D14: Pemasangan 1 m2 rangka atap pelana baja ringan (canai dingin) profil C75 | E14: =3.12*2 -> 6.24 | F14: =VLOOKUP(D14,'AHSP MCK'!D:K,8,FALSE) -> 177400 | G14: =E14*F14 -> 1106976
B15: 2.2.1.1.3 | C15: BIDANG CIPTA KARYA | D15: 1 kg Penulangan Kolom, Balok, Ring Balk dan Sloof untuk BjTP diameter <12 mm cara Manual | F15: =VLOOKUP(D15,'AHSP MCK'!D:K,7,FALSE) -> 0 | G15: =E15*F15 -> 0
B16: 2.2.1.3.2 | C16: BIDANG CIPTA KARYA | D16: Pemasangan 1 m2 bekisting untuk sloof (3 kali pakai) | F16: =VLOOKUP(D16,'AHSP MCK'!D:K,7,FALSE) -> 0 | G16: =E16*F16 -> 0
B17: 2.2.1.3.2 | C17: BIDANG CIPTA KARYA | D17: Pemasangan 1 m2 bekisting untuk sloof (3 kali pakai) | F17: =VLOOKUP(D17,'AHSP MCK'!D:K,7,FALSE) -> 0 | G17: =E17*F17 -> 0
B18: 2.2.1.3.3 | C18: BIDANG CIPTA KARYA | D18: Pemasangan 1 m2 bekisting untuk kolom (3 kali pakai) | F18: =VLOOKUP(D18,'AHSP MCK'!D:K,7,FALSE) -> 0 | G18: =E18*F18 -> 0
B19: 2.2.1.3.4 | C19: BIDANG CIPTA KARYA | D19: Pemasangan 1 m2 bekisting untuk balok (3 kali pakai) | F19: =VLOOKUP(D19,'AHSP MCK'!D:K,7,FALSE) -> 0 | G19: =E19*F19 -> 0
B20: 2.2.1.3.5 | C20: BIDANG CIPTA KARYA | D20: Pemasangan 1 m2 bekisting untuk plat lantai (3 kali pakai) | F20: =VLOOKUP(D20,'AHSP MCK'!D:K,7,FALSE) -> 0 | G20: =E20*F20 -> 0
B21: 2.2.1.4.5 | C21: BIDANG CIPTA KARYA | D21: 1 m3 beton mutu sedang f'c 20 MPa, slump (100 ± 25) mm, agregat maks 19 mm secara manual | F21: =VLOOKUP(D21,'AHSP MCK'!D:K,7,FALSE) -> 0 | G21: =E21*F21 -> 0
B22: 2.2.1.10.1 | C22: BIDANG CIPTA KARYA | D22: Pembuatan 1 m' kolom praktis beton bertulang (11x11) | E22: =(2.4*2)+(2*1.8) -> 8.4 | F22: =VLOOKUP(D22,'AHSP MCK'!D:K,7,FALSE) -> 0 | G22: =E22*F22 -> 0
B23: 2.2.1.10.2 | C23: BIDANG CIPTA KARYA | D23: Pembuatan 1 m' balok praktis beton bertulang (10x15) | E23: =(1.9*2)+(1.2*2)+(1.9*2)+(1.5*2) -> 13 | F23: =VLOOKUP(D23,'AHSP MCK'!D:K,7,FALSE) -> 0 | G23: =E23*F23 -> 0 | I23: =0.1*0.15*(1.5+1.5+1.9+1.9) -> 0.102
B24: 2.2.2.1.8 | C24: BIDANG CIPTA KARYA | D24: Pemasangan 1 m3 pondasi batu belah mortar tipe O 2,4 Mpa (setara 1SP : 5PP), cara manual | E24: =((0.2+0.4)/2*0.4*(1.9+1.9+1.5+1.5)) -> 0.816 | F24: =VLOOKUP(D24,'AHSP MCK'!D:K,7,FALSE) -> 0 | G24: =E24*F24 -> 0 | I24: =I23*2 -> 0.204
B25: 3.1.3.7 | C25: BIDANG CIPTA KARYA | D25: Pemasangan 1 m2 atap metal lembaran | E25: =E14 -> 6.24 | F25: =VLOOKUP(D25,'AHSP MCK'!D:K,7,FALSE) -> 0 | G25: =E25*F25 -> 0
B26: 3.3.6 | C26: BIDANG CIPTA KARYA | D26: Pemasangan 1 m' lisplank non kayu (GRC, serat semen) lebar 20 cm | E26: =3.12+3.12+2+0.5 -> 8.74 | F26: =VLOOKUP(D26,'AHSP MCK'!D:K,7,FALSE) -> 0 | G26: =E26*F26 -> 0
B27: 3.5.2.1 | C27: BIDANG CIPTA KARYA | D27: Pemasangan 1 m2 plafon papan gypsum tebal 9 mm | E27: =1.2*1.6 -> 1.92 | F27: =VLOOKUP(D27,'AHSP MCK'!D:K,7,FALSE) -> 0 | G27: =E27*F27 -> 0
B28: 3.5.2.6 | C28: BIDANG CIPTA KARYA | D28: Pemasangan 1 m' list plafon gypsum | F28: =VLOOKUP(D28,'AHSP MCK'!D:K,7,FALSE) -> 0 | G28: =E28*F28 -> 0
B29: 3.5.3.1 | C29: BIDANG CIPTA KARYA | D29: Pemasangan 1 m2 rangka plafon besi hollow 40.40, modul 60x60 cm | E29: =E27 -> 1.92 | F29: =VLOOKUP(D29,'AHSP MCK'!D:K,7,FALSE) -> 0 | G29: =E29*F29 -> 0
B30: 3.6.3.4 | C30: BIDANG CIPTA KARYA | D30: Pemasangan 1 m2 glass block 20x20 cm, 1PC : 3PP | F30: =VLOOKUP(D30,'AHSP MCK'!D:K,7,FALSE) -> 0 | G30: =E30*F30 -> 0
B31: 3.6.3.5 | C31: BIDANG CIPTA KARYA | D31: Pemasangan 1 m2 dinding kerawang (rooster) 20x20 (Setara Campuran 1SP : 3PP) | E31: 2 | F31: =VLOOKUP(D31,'AHSP MCK'!D:K,7,FALSE) -> 0 | G31: =E31*F31 -> 0
B32: 3.6.4.2 | C32: BIDANG CIPTA KARYA | D32: Pemasangan 1 m2 dinding bata ringan tebal 7.5 cm dengan mortar siap pakai | E32: =(1.2*2.7)+(1.2*2.1)+(1.6*2.1*2)+(0.5*1.6*0.4*2)-(0.7*2)-(0.2*0.2*2) -> 11.64 | F32: =VLOOKUP(D32,'AHSP MCK'!D:K,7,FALSE) -> 0 | G32: =E32*F32 -> 0
B33: 3.7.5 | C33: BIDANG CIPTA KARYA | D33: Pemasangan 1 m2 plesteran 1SP : 5PP tebal 15 mm | E33: =(E32*2)-E38 -> 18.38 | F33: =VLOOKUP(D33,'AHSP MCK'!D:K,7,FALSE) -> 0 | G33: =E33*F33 -> 0
B34: 3.7.8 | C34: BIDANG CIPTA KARYA | D34: Pemasangan 1 m2 acian | E34: =E33 -> 18.38 | F34: =VLOOKUP(D34,'AHSP MCK'!D:K,7,FALSE) -> 0 | G34: =E34*F34 -> 0
B35: 3.8.10.1 | C35: BIDANG CIPTA KARYA | D35: Pengecatan 1 m2 tembok baru Interior( 1 lapis cat dasar, 2 lapis cat penutup) | E35: =E34 -> 18.38 | F35: =VLOOKUP(D35,'AHSP MCK'!D:K,7,FALSE) -> 0 | G35: =E35*F35 -> 0
B36: 3.8.20.1 | C36: BIDANG CIPTA KARYA | D36: Pengecatan 1 m2 plafon Interior ( 1 lapis Cat Dasar dan 2 Lapis Cat Penutup) | E36: =E29 -> 1.92 | F36: =VLOOKUP(D36,'AHSP MCK'!D:K,7,FALSE) -> 0 | G36: =E36*F36 -> 0
B37: 3.9.7.3 | C37: BIDANG CIPTA KARYA | D37: Pemasangan 1 m2 lantai keramik artistik uk. 20x20 cm (1SP : 2PP) | E37: =2.75*1.5 -> 4.125 | F37: =VLOOKUP(D37,'AHSP MCK'!D:K,7,FALSE) -> 0 | G37: =E37*F37 -> 0
B38: 3.10.1.4 | C38: BIDANG CIPTA KARYA | D38: Pemasangan 1 m2 dinding keramik uk. 20x20 cm (1SP : 2PP) | E38: =(1*(1.2+1.2+1.6+1.6))-(1*0.7) -> 4.9 | F38: =VLOOKUP(D38,'AHSP MCK'!D:K,7,FALSE) -> 0 | G38: =E38*F38 -> 0
B39: 3.11.1.4 | C39: BIDANG CIPTA KARYA | D39: Pemasangan 1 m2 pintu aluminium strip lebar 8 cm | E39: =2*0.7 -> 1.4 | F39: =VLOOKUP(D39,'AHSP MCK'!D:K,7,FALSE) -> 0 | G39: =E39*F39 -> 0
B40: 3.18.1.1 | C40: BIDANG CIPTA KARYA | D40: Pemasangan 1 buah wastafel | F40: =VLOOKUP(D40,'AHSP MCK'!D:K,7,FALSE) -> 0 | G40: =E40*F40 -> 0
B41: 3.18.3.2 | C41: BIDANG CIPTA KARYA | D41: Pemasangan 1 buah closet jongkok | E41: 1 | F41: =VLOOKUP(D41,'AHSP MCK'!D:K,7,FALSE) -> 0 | G41: =E41*F41 -> 0
B42: 3.18.6.1 | C42: BIDANG CIPTA KARYA | D42: Pemasangan 1 buah floor drain stainless steel | E42: 1 | F42: =VLOOKUP(D42,'AHSP MCK'!D:K,7,FALSE) -> 0 | G42: =E42*F42 -> 0
...

Sheet Harga Satuan
B2: DAFTAR HARGA SATUAN PEKERJAAN (DHSP)
B3: BIDANG CIPTA KARYA
B4: Berdasarkan SE Bina Konstruksi Nomor 30/SE/Dk/2025
B6: NO | C6: URAIAN PEKERJAAN | D6: SATUAN | E6: HARGA SATUAN | F6: KETERANGAN
B7: =Persiapan!C2 -> 1. | C7: =VLOOKUP(B7,Persiapan!C:M,2,FALSE) -> PERSIAPAN LAPANGAN / SITE WORK
B8: =Persiapan!C3 -> 1.1 | C8: =VLOOKUP(B8,Persiapan!C:M,2,FALSE) -> PEKERJAAN PERSIAPAN
B9: =Persiapan!C4 -> 1.1.1 | C9: =VLOOKUP(B9,Persiapan!C:M,2,FALSE) -> Pembuatan Pagar Proyek
B10: =Persiapan!C5 -> 1.1.1.1 | C10: =VLOOKUP(B10,Persiapan!C:M,2,FALSE) -> Pembuatan 1 m’ pagar sementara dari kayu tinggi 2 meter | D10: m' | E10: =VLOOKUP(C10,Persiapan!$D$5:$K$679,8,FALSE) -> 348000 | F10: =VLOOKUP(C10,Persiapan!$D$5:$M$679,10,FALSE) -> - | G10: =VLOOKUP(C10,Persiapan!$D$5:$L$679,9,FALSE) -> -
B11: =Persiapan!C30 -> 1.1.1.2 | C11: =VLOOKUP(B11,Persiapan!C:M,2,FALSE) -> Pembuatan 1 m’ pagar sementara dari seng gelombang rangka kayu tinggi 2 meter | D11: m' | E11: =VLOOKUP(C11,Persiapan!$D$5:$K$679,8,FALSE) -> 245600 | F11: =VLOOKUP(C11,Persiapan!$D$5:$M$679,10,FALSE) -> 0 | G11: =VLOOKUP(C11,Persiapan!$D$5:$L$679,9,FALSE) -> 0
B12: =Persiapan!C54 -> 1.1.1.3 | C12: =VLOOKUP(B12,Persiapan!C:M,2,FALSE) -> Pembuatan 1 m’ pagar sementara dari kawat duri tinggi 2 meter | D12: m' | E12: =VLOOKUP(C12,Persiapan!$D$5:$K$679,8,FALSE) -> 206200 | F12: =VLOOKUP(C12,Persiapan!$D$5:$M$679,10,FALSE) -> Revisis | G12: =VLOOKUP(C12,Persiapan!$D$5:$L$679,9,FALSE) -> tidak ada perubahan
B13: =Persiapan!C78 -> 1.1.1.4 | C13: =VLOOKUP(B13,Persiapan!C:M,2,FALSE) -> Pembuatan 1 m’ pagar sementara seng gelombang rangka baja L.40.40.4 tinggi pagar 1.8 meter | D13: m' | E13: =VLOOKUP(C13,Persiapan!$D$5:$K$679,8,FALSE) -> 275500 | F13: =VLOOKUP(C13,Persiapan!$D$5:$M$679,10,FALSE) -> - | G13: =VLOOKUP(C13,Persiapan!$D$5:$L$679,9,FALSE) -> -
B14: =Persiapan!C98 -> 1.1.1.5 | C14: =VLOOKUP(B14,Persiapan!C:M,2,FALSE) -> Pembuatan 1 m2 pagar BRC Galvanis | D14: m2 | E14: =VLOOKUP(C14,Persiapan!$D$5:$K$679,8,FALSE) -> #VALUE! | F14: =VLOOKUP(C14,Persiapan!$D$5:$M$679,10,FALSE) -> - | G14: =VLOOKUP(C14,Persiapan!$D$5:$L$679,9,FALSE) -> -
B15: =Persiapan!C115 -> 1.1.1.6 | C15: =VLOOKUP(B15,Persiapan!C:M,2,FALSE) -> Pemasangan 1 m2 panel beton pracetak 50x50x240 untuk pagar | D15: m2 | E15: =VLOOKUP(C15,Persiapan!$D$5:$K$679,8,FALSE) -> 186000 | F15: =VLOOKUP(C15,Persiapan!$D$5:$M$679,10,FALSE) -> Revisi | G15: =VLOOKUP(C15,Persiapan!$D$5:$L$679,9,FALSE) -> tidak ada perubahan
B16: =Persiapan!C137 -> 1.1.2 | C16: =VLOOKUP(B16,Persiapan!C:M,2,FALSE) -> Alat dan/atau sarana penunjang | E16: =VLOOKUP(C16,Persiapan!$D$5:$K$679,8,FALSE) -> 0 | F16: =VLOOKUP(C16,Persiapan!$D$5:$M$679,10,FALSE) -> 0 | G16: =VLOOKUP(C16,Persiapan!$D$5:$L$679,9,FALSE) -> 0
B17: =Persiapan!C139 -> 1.1.2.1 | C17: =VLOOKUP(B17,Persiapan!C:M,2,FALSE) -> 1 buah papan nama pekerjaan ukuran 0.8x1.2 menggunakan multiflex 18 mm, frame besi siku dan tiang kayu 8/12 | D17: buah | E17: =VLOOKUP(C17,Persiapan!$D$5:$K$679,8,FALSE) -> 809500 | F17: =VLOOKUP(C17,Persiapan!$D$5:$M$679,10,FALSE) -> - | G17: =VLOOKUP(C17,Persiapan!$D$5:$L$679,9,FALSE) -> -
B18: =Persiapan!C164 -> 1.1.2.2 | C18: =VLOOKUP(B18,Persiapan!C:M,2,FALSE) -> 1 buah papan nama pekerjaan ukuran 0.6x08 menggunakan multiplex 10 mm, frame allumunium siku dan tiang kayu 5/7, printing banner plastik | D18: buah | E18: =VLOOKUP(C18,Persiapan!$D$5:$K$679,8,FALSE) -> 407100 | F18: =VLOOKUP(C18,Persiapan!$D$5:$M$679,10,FALSE) -> - | G18: =VLOOKUP(C18,Persiapan!$D$5:$L$679,9,FALSE) -> -
B19: =Persiapan!C188 -> 1.1.2.3 | C19: =VLOOKUP(B19,Persiapan!C:M,2,FALSE) -> Pembuatan 1 m2 kantor sementara/rumah jaga/gudang semen dan peralatan lantai plesteran, dinding setengah tembok | D19: m2 | E19: =VLOOKUP(C19,Persiapan!$D$5:$K$679,8,FALSE) -> 938400 | F19: =VLOOKUP(C19,Persiapan!$D$5:$M$679,10,FALSE) -> - | G19: =VLOOKUP(C19,Persiapan!$D$5:$L$679,9,FALSE) -> -
B20: =Persiapan!C219 -> 1.1.2.4 | C20: =VLOOKUP(B20,Persiapan!C:M,2,FALSE) -> Pembuatan 1 m2 direksi keet (Kantor), los kerja dan gudang | D20: m2 | E20: =VLOOKUP(C20,Persiapan!$D$5:$K$679,8,FALSE) -> 2086200 | F20: =VLOOKUP(C20,Persiapan!$D$5:$M$679,10,FALSE) -> Revisi | G20: =VLOOKUP(C20,Persiapan!$D$5:$L$679,9,FALSE) -> tidak ada perbahan
B21: =Persiapan!C246 -> 1.1.2.5 | C21: =VLOOKUP(B21,Persiapan!C:M,2,FALSE) -> Pembuatan 1 m2 jalan sementara lapis macadam | D21: m2 | E21: =VLOOKUP(C21,Persiapan!$D$5:$K$679,8,FALSE) -> 1262000 | F21: =VLOOKUP(C21,Persiapan!$D$5:$M$679,10,FALSE) -> - | G21: =VLOOKUP(C21,Persiapan!$D$5:$L$679,9,FALSE) -> -
B22: =Persiapan!C270 -> 1.1.2.6 | C22: =VLOOKUP(B22,Persiapan!C:M,2,FALSE) -> Pembuatan 1 m2 jalan sementara (Jalan Tanah) | D22: m2 | E22: =VLOOKUP(C22,Persiapan!$D$5:$K$679,8,FALSE) -> 128900 | F22: =VLOOKUP(C22,Persiapan!$D$5:$M$679,10,FALSE) -> - | G22: =VLOOKUP(C22,Persiapan!$D$5:$L$679,9,FALSE) -> -
B23: =Persiapan!C286 -> 1.1.2.7 | C23: =VLOOKUP(B23,Persiapan!C:M,2,FALSE) -> Pembuatan 1 m2 jalan sementara (Jalan Kerikil) | D23: m2 | E23: =VLOOKUP(C23,Persiapan!$D$5:$K$679,8,FALSE) -> 190800 | F23: =VLOOKUP(C23,Persiapan!$D$5:$M$679,10,FALSE) -> - | G23: =VLOOKUP(C23,Persiapan!$D$5:$L$679,9,FALSE) -> -
B24: =Persiapan!C303 -> 1.1.3 | C24: =VLOOKUP(B24,Persiapan!C:M,2,FALSE) -> Pembersihan dan Pengupasan Permukaan Tanah
B25: =Persiapan!C304 -> 1.1.3.1 | C25: =VLOOKUP(B25,Persiapan!C:M,2,FALSE) -> 1 m3 Pembersihan dan pengupasan permukaan tanah (striping) s.d. tanaman ∅ 2 cm | D25: m2 | E25: =VLOOKUP(C25,Persiapan!$D$5:$K$679,8,FALSE) -> 11800 | F25: =VLOOKUP(C25,Persiapan!$D$5:$M$679,10,FALSE) -> - | G25: =VLOOKUP(C25,Persiapan!$D$5:$L$679,9,FALSE) -> -
B26: =Persiapan!C318 -> 1.1.3.2 | C26: =VLOOKUP(B26,Persiapan!C:M,2,FALSE) -> Tebas tebang 1 m2 tanaman/tumbuhan ∅ < 5 cm | D26: m2 | E26: =VLOOKUP(C26,Persiapan!$D$5:$K$679,8,FALSE) -> 3800 | F26: =VLOOKUP(C26,Persiapan!$D$5:$M$679,10,FALSE) -> - | G26: =VLOOKUP(C26,Persiapan!$D$5:$L$679,9,FALSE) -> -
B27: =Persiapan!C332 -> 1.1.3.3. | C27: =VLOOKUP(B27,Persiapan!C:M,2,FALSE) -> Tebas tebang 1 m 2 tanaman/tumbuhan ∅ >5 s.d. 15 cm | D27: m2 | E27: =VLOOKUP(C27,Persiapan!$D$5:$K$679,8,FALSE) -> 6300 | F27: =VLOOKUP(C27,Persiapan!$D$5:$M$679,10,FALSE) -> - | G27: =VLOOKUP(C27,Persiapan!$D$5:$L$679,9,FALSE) -> -
B28: =Persiapan!C346 -> 1.1.3.4 | C28: =VLOOKUP(B28,Persiapan!C:M,2,FALSE) -> Tebas tebang 1 batang pohon/tumbuhan ∅ >15 s.d. 30 cm | D28: btg | E28: =VLOOKUP(C28,Persiapan!$D$5:$K$679,8,FALSE) -> 21900 | F28: =VLOOKUP(C28,Persiapan!$D$5:$M$679,10,FALSE) -> - | G28: =VLOOKUP(C28,Persiapan!$D$5:$L$679,9,FALSE) -> -
B29: =Persiapan!C361 -> 1.1.3.5 | C29: =VLOOKUP(B29,Persiapan!C:M,2,FALSE) -> Tebas tebang 1 batang pohon/tumbuhan ∅ > 30 s.d 50 cm | D29: btg | E29: =VLOOKUP(C29,Persiapan!$D$5:$K$679,8,FALSE) -> 22100 | F29: =VLOOKUP(C29,Persiapan!$D$5:$M$679,10,FALSE) -> - | G29: =VLOOKUP(C29,Persiapan!$D$5:$L$679,9,FALSE) -> -
B30: =Persiapan!C376 -> 1.1.3.6 | C30: =VLOOKUP(B30,Persiapan!C:M,2,FALSE) -> Tebas tebang 1 batang pohon/tumbuhan ∅ > 50 s.d 75 cm (diameter pohon diukur 1 m di atas permukaan tanah) | D30: btg | E30: =VLOOKUP(C30,Persiapan!$D$5:$K$679,8,FALSE) -> 48000 | F30: =VLOOKUP(C30,Persiapan!$D$5:$M$679,10,FALSE) -> - | G30: =VLOOKUP(C30,Persiapan!$D$5:$L$679,9,FALSE) -> -
B31: =Persiapan!C391 -> 1.1.3.7 | C31: =VLOOKUP(B31,Persiapan!C:M,2,FALSE) -> Tebas tebang 1 batang pohon/tumbuhan ∅ > 75 cm (diameter pohon diukur 1 m di atas permukaan tanah) | D31: btg | E31: =VLOOKUP(C31,Persiapan!$D$5:$K$679,8,FALSE) -> 61600 | F31: =VLOOKUP(C31,Persiapan!$D$5:$M$679,10,FALSE) -> - | G31: =VLOOKUP(C31,Persiapan!$D$5:$L$679,9,FALSE) -> -
B32: =Persiapan!C406 -> 1.1.3.8 | C32: =VLOOKUP(B32,Persiapan!C:M,2,FALSE) -> Gali dan cabut 1 tunggul pohon tanaman keras ∅ > 5 s.d. 15 cm (termasuk pembuangan sisa tunggul tanpa menutup kembali bekas lubang) | D32: tgl | E32: =VLOOKUP(C32,Persiapan!$D$5:$K$679,8,FALSE) -> 47900 | F32: =VLOOKUP(C32,Persiapan!$D$5:$M$679,10,FALSE) -> - | G32: =VLOOKUP(C32,Persiapan!$D$5:$L$679,9,FALSE) -> -
B33: =Persiapan!C421 -> 1.1.3.9 | C33: =VLOOKUP(B33,Persiapan!C:M,2,FALSE) -> Gali dan cabut 1 tunggul pohon tanaman keras ∅ > 15 cm s.d. 30 cm (termasuk pembuangan sisa tunggul tanpa menutup kembali bekas lubang) | D33: tgl | E33: =VLOOKUP(C33,Persiapan!$D$5:$K$679,8,FALSE) -> 67500 | F33: =VLOOKUP(C33,Persiapan!$D$5:$M$679,10,FALSE) -> - | G33: =VLOOKUP(C33,Persiapan!$D$5:$L$679,9,FALSE) -> -
B34: =Persiapan!C436 -> 1.1.3.10 | C34: =VLOOKUP(B34,Persiapan!C:M,2,FALSE) -> Gali dan cabut 1 tunggul pohon tanaman keras ∅ > 30 cm s.d. 50 cm (termasuk pembuangan sisa tunggul tanpa menutup kembali bekas lubang) | D34: tgl | E34: =VLOOKUP(C34,Persiapan!$D$5:$K$679,8,FALSE) -> 95800 | F34: =VLOOKUP(C34,Persiapan!$D$5:$M$679,10,FALSE) -> - | G34: =VLOOKUP(C34,Persiapan!$D$5:$L$679,9,FALSE) -> -
B35: =Persiapan!C451 -> 1.1.3.11 | C35: =VLOOKUP(B35,Persiapan!C:M,2,FALSE) -> Gali dan cabut 1 tunggul pohon tanaman keras ∅ > 50 cm s.d. 75 cm (termasuk pembuangan sisa tunggul tanpa menutup kembali bekas lubang) | D35: tgl | E35: =VLOOKUP(C35,Persiapan!$D$5:$K$679,8,FALSE) -> 148800 | F35: =VLOOKUP(C35,Persiapan!$D$5:$M$679,10,FALSE) -> - | G35: =VLOOKUP(C35,Persiapan!$D$5:$L$679,9,FALSE) -> -
B36: =Persiapan!C466 -> 1.1.3.12 | C36: =VLOOKUP(B36,Persiapan!C:M,2,FALSE) -> Gali dan cabut 1 tunggul pohon tanaman keras ∅ > 75 cm (termasuk pembuangan sisa tunggul tanpa menutup kembali bekas lubang) | D36: tgl | E36: =VLOOKUP(C36,Persiapan!$D$5:$K$679,8,FALSE) -> 216700 | F36: =VLOOKUP(C36,Persiapan!$D$5:$M$679,10,FALSE) -> - | G36: =VLOOKUP(C36,Persiapan!$D$5:$L$679,9,FALSE) -> -
B37: =Persiapan!C481 -> 1.1.3.13 | C37: =VLOOKUP(B37,Persiapan!C:M,2,FALSE) -> Gali dan cabut 1 tunggul pohon tanaman keras ∅ > 5 s.d. 15 cm (termasuk pembuangan sisa tunggul dengan menutup kembali bekas lubang) | D37: tgl | E37: =VLOOKUP(C37,Persiapan!$D$5:$K$679,8,FALSE) -> 48900 | F37: =VLOOKUP(C37,Persiapan!$D$5:$M$679,10,FALSE) -> - | G37: =VLOOKUP(C37,Persiapan!$D$5:$L$679,9,FALSE) -> -
B38: =Persiapan!C496 -> 1.1.3.14 | C38: =VLOOKUP(B38,Persiapan!C:M,2,FALSE) -> Gali dan cabut 1 tunggul pohon tanaman keras ∅ > 15 cm s.d. 30 cm (termasuk pembuangan sisa tunggul dengan menutup kembali bekas lubang) | D38: tgl | E38: =VLOOKUP(C38,Persiapan!$D$5:$K$679,8,FALSE) -> 78000 | F38: =VLOOKUP(C38,Persiapan!$D$5:$M$679,10,FALSE) -> - | G38: =VLOOKUP(C38,Persiapan!$D$5:$L$679,9,FALSE) -> -
B39: =Persiapan!C512 -> 1.1.3.15 | C39: =VLOOKUP(B39,Persiapan!C:M,2,FALSE) -> Gali dan cabut 1 tunggul pohon tanaman keras ∅ > 15 cm s.d. 50 cm (termasuk pembuangan sisa tunggul dengan menutup kembali bekas lubang) | D39: Ha | E39: =VLOOKUP(C39,Persiapan!$D$5:$K$679,8,FALSE) -> 111900 | F39: =VLOOKUP(C39,Persiapan!$D$5:$M$679,10,FALSE) -> - | G39: =VLOOKUP(C39,Persiapan!$D$5:$L$679,9,FALSE) -> -
B40: =Persiapan!C527 -> 1.1.3.16 | C40: =VLOOKUP(B40,Persiapan!C:M,2,FALSE) -> Gali dan cabut 1 tunggul pohon tanaman keras ∅ > 15 cm s.d. 75 cm (termasuk pembuangan sisa tunggul dengan menutup kembali bekas lubang) | D40: m' | E40: =VLOOKUP(C40,Persiapan!$D$5:$K$679,8,FALSE) -> 175600 | F40: =VLOOKUP(C40,Persiapan!$D$5:$M$679,10,FALSE) -> - | G40: =VLOOKUP(C40,Persiapan!$D$5:$L$679,9,FALSE) -> -
B41: =Persiapan!C543 -> 1.1.3.17 | C41: =VLOOKUP(B41,Persiapan!C:M,2,FALSE) -> Gali dan cabut 1 tunggul pohon tanaman keras ∅ > 75 cm (termasuk pembuangan sisa tunggul dengan menutup kembali bekas lubang) | D41: m' | E41: =VLOOKUP(C41,Persiapan!$D$5:$K$679,8,FALSE) -> 268600 | F41: =VLOOKUP(C41,Persiapan!$D$5:$M$679,10,FALSE) -> - | G41: =VLOOKUP(C41,Persiapan!$D$5:$L$679,9,FALSE) -> -
B42: =Persiapan!C559 -> 1.1.4 | C42: =VLOOKUP(B42,Persiapan!C:M,2,FALSE) -> Pengukuran dan Pasangan Bouwplank | E42: =VLOOKUP(C42,Persiapan!$D$5:$K$679,8,FALSE) -> 0 | F42: =VLOOKUP(C42,Persiapan!$D$5:$M$679,10,FALSE) -> 0 | G42: =VLOOKUP(C42,Persiapan!$D$5:$L$679,9,FALSE) -> 0
...

Sheet RAB
B2: REKAPITULASI RENCANA ANGGARAN BIAYA
B3: UNIT KERJA | D3: : DINAS PERUMAHAN DAN KAWASAN PERMUKIMAN
B4: PROGRAM | D4: : PROGRAM PENGELOLAAN DAN PENGEMBANGAN SISTEM AIR LIMBAH
B5: KEGIATAN | D5: : PENGELOLAAN DAN PENGEMBANGAN SISTEM AIR LIMBAH DOMESTIK DALAM
D6: DAERAH KABUPATEN/KOTA
B7: PEKERJAAN | D7: : PEMBANGUNAN MCK INDIVIDU DESA CILOTO KEC. CIPANAS
B8: LOKASI PEKERJAAN | D8: : DESA CILOTO KECAMATAN CIPANAS
B9: SUMBER DANA | D9: : DAU
B10: TAHUN ANGGARAN | D10: : 2026
B12: No | C12: Item Pekerjaan | E12: Satuan | F12: Volume | G12: Harga Satuan | H12: Jumlah Harga Satuan
B15: =B79 -> I | C15: =C79 -> Pekerjaan Persiapan | E15: paket | F15: 1 | G15: =H83 -> 200000 | H15: =F15*G15 -> 200000
B16: =B85 -> II | C16: =C85 -> SMKK | E16: paket | F16: 1 | G16: =H94 -> 495000 | H16: =F16*G16 -> 495000
B17: =B95 -> III | C17: =C95 -> Lokasi I
B18: =B96 -> III | C18: =C96 -> Pekerjaan Tanah | E18: paket | F18: 1 | G18: =H102 -> 0 | H18: =F18*G18 -> 0
B19: =B104 -> IV | C19: =C104 -> Pekerjaan Pondasi | E19: paket | F19: 1 | G19: =H107 -> 0 | H19: =F19*G19 -> 0
B20: =B109 -> A | C20: =C109 -> Pekerjaan Beton | E20: paket | F20: 1 | G20: =H145 -> 0 | H20: =F20*G20 -> 0
B21: =B147 -> A | C21: =C147 -> Pekerjaan Dinding | E21: paket | F21: 1 | G21: =H154 -> 197751 | H21: =F21*G21 -> 197751
B22: =B156 -> B | C22: =C156 -> Pekerjaan Penutup Lantai dan Dinding | E22: paket | F22: 1 | G22: =H161 -> 3598262.4 | H22: =F22*G22 -> 3598262.4
B23: =B163 -> C | C23: =C163 -> Pekerjaan Atap | E23: paket | F23: 1 | G23: =H168 -> 584797.5 | H23: =F23*G23 -> 584797.5
B24: =B170 -> D | C24: =C170 -> Pekerjaan Langit-Langit | E24: paket | F24: 1 | G24: =H175 -> 419265.6 | H24: =F24*G24 -> 419265.6
B25: =B177 -> E | C25: =C177 -> Pekerjaan Pengecatan | E25: paket | F25: 1 | G25: =H181 -> 1255508 | H25: =F25*G25 -> 1255508
B26: =B183 -> F | C26: =C183 -> Pekerjaan Sanitasi | E26: paket | F26: 1 | G26: =H196 -> 5135900 | H26: =F26*G26 -> 5135900
B27: =B198 -> G | C27: =C198 -> Pekerjaan Tangki Septik | E27: paket | F27: 1 | G27: =H218 -> 5622639.6 | H27: =F27*G27 -> 5622639.6
B28: =B220 -> H | C28: =C220 -> Pekerjaan Listrik | E28: paket | F28: 1 | G28: =H228 -> 606100 | H28: =F28*G28 -> 606100
B29: =B230 -> I | C29: =C230 -> Pekerjaan Lain-Lain | E29: paket | F29: 1 | G29: =H236 -> 2116798 | H29: =F29*G29 -> 2116798 | O29: =SUM(H18:H29) -> 19537022
B30: =B237 -> IV | C30: =C237 -> Lokasi II
B31: =B238 -> A | C31: =C238 -> Pekerjaan Tanah | E31: paket | F31: 1 | G31: =H244 -> 0 | H31: =F31*G31 -> 0
B32: =B246 -> IV | C32: =C246 -> Pekerjaan Pondasi | E32: paket | F32: 1 | G32: =H249 -> 0 | H32: =F32*G32 -> 0
B33: =B251 -> V | C33: =C251 -> Pekerjaan Beton | E33: paket | F33: 1 | G33: =H287 -> 0 | H33: =F33*G33 -> 0
B34: =B289 -> A | C34: =C289 -> Pekerjaan Dinding | E34: paket | F34: 1 | G34: =H296 -> 796582.5 | H34: =F34*G34 -> 796582.5
B35: =B298 -> B | C35: =C298 -> Pekerjaan Penutup Lantai dan Dinding | E35: paket | F35: 1 | G35: =H303 -> 6157750.1 | H35: =F35*G35 -> 6157750.1
B36: =B305 -> C | C36: =C305 -> Pekerjaan Atap | E36: paket | F36: 1 | G36: =H310 -> 2887680.8 | H36: =F36*G36 -> 2887680.8
B37: =B312 -> D | C37: =C312 -> Pekerjaan Langit-Langit | E37: paket | F37: 1 | G37: =H317 -> 1182238.5 | H37: =F37*G37 -> 1182238.5
B38: =B319 -> E | C38: =C319 -> Pekerjaan Pengecatan | E38: paket | F38: 1 | G38: =H323 -> 2249992.5 | H38: =F38*G38 -> 2249992.5
B39: =B325 -> F | C39: =C325 -> Pekerjaan Sanitasi | E39: paket | F39: 1 | G39: =H338 -> 3186800 | H39: =F39*G39 -> 3186800
B40: =B340 -> G | C40: =C340 -> Pekerjaan Tangki Septik | E40: paket | F40: 1 | G40: =H360 -> 5622639.6 | H40: =F40*G40 -> 5622639.6
B41: =B362 -> H | C41: =C362 -> Pekerjaan Listrik | E41: paket | F41: 1 | G41: =H370 -> 606100 | H41: =F41*G41 -> 606100
B42: =B372 -> I | C42: =C372 -> Pekerjaan Lain-Lain | E42: paket | F42: 1 | G42: =H378 -> 2126798 | H42: =F42*G42 -> 2126798 | O42: =SUM(H31:H42) -> 24816582
C44: Jumlah | H44: =SUM(H15:H42) -> 45048604
C45: PPN | F45: 0.11 | H45: =H44*F45 -> 4955346.4
...

Sheet RAB (2)
B2: REKAPITULASI RENCANA ANGGARAN BIAYA
B3: UNIT KERJA : DINAS PERUMAHAN DAN KAWASAN PERMUKIMAN
B4: PROGRAM : PROGRAM PENGELOLAAN DAN PENGEMBANGAN SISTEM AIR LIMBAH
B5: KEGIATAN : PENGELOLAAN DAN PENGEMBANGAN SISTEM AIR LIMBAH DOMESTIK DALAM DAERAH KABUPATEN/KOTA
B6: PEKERJAAN :
B7: LOKASI PEKERJAAN :
B8: SUMBER DANA :
B9: TAHUN ANGGARAN :
B11: No | C11: Item Pekerjaan | D11: Satuan | E11: Volume | F11: Harga Satuan | G11: Jumlah Harga Satuan
B14: =B68 -> I | C14: =C68 -> Pekerjaan Persiapan | D14: paket | E14: 1 | F14: =G72 -> 1733880 | G14: =E14*F14 -> 1733880
B15: =B74 -> II | C15: =C74 -> SMKK | D15: paket | E15: 1 | F15: =G83 -> 647500 | G15: =E15*F15 -> 647500
B16: =B85 -> III | C16: =C85 -> Pekerjaan Tanah | D16: paket | E16: 1 | F16: =G91 -> 146662.4 | G16: =E16*F16 -> 146662.4
B17: =B93 -> IV | C17: =C93 -> Pekerjaan Pondasi | D17: paket | E17: 1 | F17: =G96 -> 829056 | G17: =E17*F17 -> 829056
B18: =B98 -> V | C18: =C98 -> Pekerjaan Beton | D18: paket | E18: 1 | F18: =G134 -> 2635800 | G18: =E18*F18 -> 2635800
B19: =B136 -> VI | C19: =C136 -> Pekerjaan Dinding | D19: paket | E19: 1 | F19: =G143 -> 3108700 | G19: =E19*F19 -> 3108700
B20: =B145 -> VII | C20: =C145 -> Pekerjaan Penutup Lantai dan Dinding | D20: paket | E20: 1 | F20: =G150 -> 2078797.5 | G20: =E20*F20 -> 2078797.5
B21: =B152 -> VIII | C21: =C152 -> Pekerjaan Atap | D21: paket | E21: 1 | F21: =G157 -> 2374552 | G21: =E21*F21 -> 2374552
B22: =B159 -> IX | C22: =C159 -> Pekerjaan Langit-Langit | D22: paket | E22: 1 | F22: =G164 -> 1109124 | G22: =E22*F22 -> 1109124
B23: =B166 -> X | C23: =C166 -> Pekerjaan Pengecatan | D23: paket | E23: 1 | F23: =G170 -> 881520 | G23: =E23*F23 -> 881520
B24: =B172 -> XI | C24: =C172 -> Pekerjaan Sanitasi | D24: paket | E24: 1 | F24: =G185 -> 1610800 | G24: =E24*F24 -> 1610800
B25: =B187 -> XII | C25: =C187 -> Pekerjaan Tangki Septik | D25: paket | E25: 1 | F25: =G205 -> 9044973 | G25: =E25*F25 -> 9044973
B26: =B207 -> XIII | C26: =C207 -> Pekerjaan Listrik | D26: paket | E26: 1 | F26: =G216 -> 387100 | G26: =E26*F26 -> 387100
B27: =B218 -> XIV | C27: =C218 -> Pekerjaan Lain-Lain | D27: paket | E27: 1 | F27: =G223 -> 1679580 | G27: =E27*F27 -> 1679580
C29: Jumlah | G29: =SUM(G14:G27) -> 28268045
C30: PPN | E30: 0.11 | G30: =G29*E30 -> 3109484.9
C31: Total | G31: =G30+G29 -> 31377530
C32: Dibulatkan | G32: =ROUNDDOWN(G31,-3) -> 31377000
C33: Terbilang | D33: =PROPER([46]!terbilang(G32))&" Rupiah" -> Tiga Puluh Satu Juta Tiga Ratus Tujuh Puluh Tujuh Ribu Rupiah
C34: Jangka Waktu Pelaksanaan | D34: 45 (Empat Puluh Lima) Hari Kalender
B56: RENCANA ANGGARAN BIAYA
B57: =B3 -> UNIT KERJA : DINAS PERUMAHAN DAN KAWASAN PERMUKIMAN
B58: =B4 -> PROGRAM : PROGRAM PENGELOLAAN DAN PENGEMBANGAN SISTEM AIR LIMBAH
B59: =B5 -> KEGIATAN : PENGELOLAAN DAN PENGEMBANGAN SISTEM AIR LIMBAH DOMESTIK DALAM DAERAH KABUPATEN/KOTA
B60: =B6 -> PEKERJAAN :
B61: =B7 -> LOKASI PEKERJAAN :
B62: =B8 -> SUMBER DANA :
B63: =B9 -> TAHUN ANGGARAN : | O63: VOL
O64: 6PK | P64: 12PK | Q64: 17PK | R64: 21PK | S64: 23PK
A65: No | B65: No | C65: Item Pekerjaan | D65: Satuan | E65: Volume | F65: Harga Satuan | G65: Jumlah Harga Satuan | H65: Bobot Pekerjaan terhadap Nilai HPS | I65: Kode Produk | J65: Bidang Master Produk | K65: Bidang SBU terkait | L65: Rekomendasi Metode Pemilihan per item pekerjaan | M65: Ket | Q65: SUMUR
G67: =G72+G83+G91+G96+G134+G143+G150+G157+G164+G170+G185+G205+G216+G223 -> 28268045 | H67: =SUM(H69:H224) -> 1
...

Sheet RAB (3)
B2: REKAPITULASI RENCANA ANGGARAN BIAYA
B3: UNIT KERJA : DINAS PERUMAHAN DAN KAWASAN PERMUKIMAN
B4: PROGRAM : PROGRAM PENGELOLAAN DAN PENGEMBANGAN SISTEM AIR LIMBAH
B5: KEGIATAN : PENGELOLAAN DAN PENGEMBANGAN SISTEM AIR LIMBAH DOMESTIK DALAM DAERAH KABUPATEN/KOTA
B6: PEKERJAAN :
B7: LOKASI PEKERJAAN :
B8: SUMBER DANA :
B9: TAHUN ANGGARAN :
B11: No | C11: Item Pekerjaan | D11: Satuan | E11: Volume | F11: Harga Satuan | G11: Jumlah Harga Satuan
B14: =B68 -> I | C14: =C68 -> Pekerjaan Persiapan | D14: paket | E14: 1 | F14: =G72 -> 475250.4 | G14: =E14*F14 -> 475250.4
B15: =B74 -> II | C15: =C74 -> SMKK | D15: paket | E15: 1 | F15: =G83 -> 647500 | G15: =E15*F15 -> 647500
B16: =B85 -> III | C16: =C85 -> Pekerjaan Tanah | D16: paket | E16: 1 | F16: =G91 -> 134884.8 | G16: =E16*F16 -> 134884.8
B17: =B93 -> IV | C17: =C93 -> Pekerjaan Pondasi | D17: paket | E17: 1 | F17: =G96 -> 901516.8 | G17: =E17*F17 -> 901516.8
B18: =B98 -> V | C18: =C98 -> Pekerjaan Beton | D18: paket | E18: 1 | F18: =G134 -> 2898800 | G18: =E18*F18 -> 2898800
B19: =B136 -> VI | C19: =C136 -> Pekerjaan Dinding | D19: paket | E19: 1 | F19: =G143 -> 3027782 | G19: =E19*F19 -> 3027782
B20: =B145 -> VII | C20: =C145 -> Pekerjaan Penutup Lantai dan Dinding | D20: paket | E20: 1 | F20: =G150 -> 2189457.5 | G20: =E20*F20 -> 2189457.5
B21: =B152 -> VIII | C21: =C152 -> Pekerjaan Atap | D21: paket | E21: 1 | F21: =G157 -> 3585888 | G21: =E21*F21 -> 3585888
B22: =B159 -> IX | C22: =C159 -> Pekerjaan Langit-Langit | D22: paket | E22: 1 | F22: =G164 -> 1326204 | G22: =E22*F22 -> 1326204
B23: =B166 -> X | C23: =C166 -> Pekerjaan Pengecatan | D23: paket | E23: 1 | F23: =G170 -> 936423 | G23: =E23*F23 -> 936423
B24: =B172 -> XI | C24: =C172 -> Pekerjaan Sanitasi | D24: paket | E24: 1 | F24: =G185 -> 1980700 | G24: =E24*F24 -> 1980700
B25: =B187 -> XII | C25: =C187 -> Pekerjaan Tangki Septik | D25: paket | E25: 1 | F25: =G205 -> 3896531.6 | G25: =E25*F25 -> 3896531.6
B26: =B207 -> XIII | C26: =C207 -> Pekerjaan Listrik | D26: paket | E26: 1 | F26: =G215 -> 606100 | G26: =E26*F26 -> 606100
B27: =B217 -> XIV | C27: =C217 -> Pekerjaan Lain-Lain | D27: paket | E27: 1 | F27: =G222 -> 2030840 | G27: =E27*F27 -> 2030840
C29: Jumlah | G29: =SUM(G14:G27) -> 24637878
C30: PPN | E30: 0.11 | G30: =G29*E30 -> 2710166.6
C31: Total | G31: =G30+G29 -> 27348045
C32: Dibulatkan | G32: =ROUNDDOWN(G31,-3) -> 27348000
C33: Terbilang | D33: =PROPER([46]!terbilang(G32))&" Rupiah" -> Dua Puluh Tujuh Juta Tiga Ratus Empat Puluh Delapan Ribu Rupiah
C34: Jangka Waktu Pelaksanaan | D34: 45 (Empat Puluh Lima) Hari Kalender
B56: RENCANA ANGGARAN BIAYA
B57: =B3 -> UNIT KERJA : DINAS PERUMAHAN DAN KAWASAN PERMUKIMAN
B58: =B4 -> PROGRAM : PROGRAM PENGELOLAAN DAN PENGEMBANGAN SISTEM AIR LIMBAH
B59: =B5 -> KEGIATAN : PENGELOLAAN DAN PENGEMBANGAN SISTEM AIR LIMBAH DOMESTIK DALAM DAERAH KABUPATEN/KOTA
B60: =B6 -> PEKERJAAN :
B61: =B7 -> LOKASI PEKERJAAN :
B62: =B8 -> SUMBER DANA :
B63: =B9 -> TAHUN ANGGARAN : | O63: VOL
O64: 6PK | P64: 12PK | Q64: 17PK | R64: 21PK | S64: 23PK
A65: No | B65: No | C65: Item Pekerjaan | D65: Satuan | E65: Volume | F65: Harga Satuan | G65: Jumlah Harga Satuan | H65: Bobot Pekerjaan terhadap Nilai HPS | I65: Kode Produk | J65: Bidang Master Produk | K65: Bidang SBU terkait | L65: Rekomendasi Metode Pemilihan per item pekerjaan | M65: Ket | Q65: SUMUR
G67: =G72+G83+G91+G96+G134+G143+G150+G157+G164+G170+G185+G205+G215+G222 -> 24637878 | H67: =SUM(H69:H223) -> 1
...

Sheet Persiapan
C2: 1. | D2: PERSIAPAN LAPANGAN / SITE WORK
C3: 1.1 | D3: PEKERJAAN PERSIAPAN
C4: 1.1.1 | D4: Pembuatan Pagar Proyek
C5: 1.1.1.1 | D5: Pembuatan 1 m’ pagar sementara dari kayu tinggi 2 meter | K5: =ROUNDDOWN(J28,-2) -> 348000 | L5: - | M5: -
C6: No | D6: Uraian | E6: Kode | F6: Sat. | G6: Koefisien | H6: Harga Satuan (Rp) | J6: Jumlah Harga (Rp)
C7: A | D7: TENAGA KERJA | N7: Catatan:
C8: 1 | D8: Pekerja | E8: L.01 | F8: OH | G8: 0.6 | H8: =VLOOKUP(D8,upahbahan,3,FALSE) -> 100000 | J8: =G8*H8 -> 60000 | N8: Biaya Umum dan Keuntungan | Q8: 0.1
C9: 2 | D9: Tukang kayu | E9: L.02 | F9: OH | G9: 0.2 | H9: =VLOOKUP(D9,upahbahan,3,FALSE) -> 135000 | J9: =G9*H9 -> 27000
C10: 3 | D10: Tukang batu | E10: L.02 | F10: OH | G10: 0.2 | H10: =VLOOKUP(D10,upahbahan,3,FALSE) -> 135000 | J10: =G10*H10 -> 27000
C11: 4 | D11: Kepala tukang | E11: L.03 | F11: OH | G11: 0.04 | H11: =VLOOKUP(D11,upahbahan,3,FALSE) -> 150000 | J11: =G11*H11 -> 6000
C12: 5 | D12: Mandor | E12: L.04 | F12: OH | G12: 0.013 | H12: =VLOOKUP(D12,upahbahan,3,FALSE) -> 160000 | J12: =G12*H12 -> 2080
C13: JUMLAH HARGA TENAGA KERJA | J13: =SUM(J8:J12) -> 122080
C14: B | D14: BAHAN
C15: 1 | D15: Kaso 5/7 kayu kelas II | F15: m3 | G15: 0.0387 | H15: =VLOOKUP(D15,upahbahan,3,FALSE) -> 3015000 | J15: =G15*H15 -> 116680.5
C16: 2 | D16: Papan Kayu ukuran 2/20 cm | F16: m3 | G16: 0.0396 | H16: =VLOOKUP(D16,upahbahan,3,FALSE) -> 0 | J16: =G16*H16 -> 0
C17: 3 | D17: Paku biasa 5 inchi | F17: kg | G17: 0.5872 | H17: =VLOOKUP(D17,upahbahan,3,FALSE) -> 20000 | J17: =G17*H17 -> 11744
C18: 4 | D18: Semen Portland (PC) | F18: kg | G18: 26.406 | H18: =VLOOKUP(D18,upahbahan,3,FALSE) -> 1530 | J18: =G18*H18 -> 40401.18
C19: 5 | D19: Pasir Beton | F19: kg | G19: 61.56 | H19: =VLOOKUP(D19,upahbahan,3,FALSE) -> 221.787 | J19: =G19*H19 -> 13653.208
C20: 6 | D20: Kerikil | F20: kg | G20: 83.349 | H20: =VLOOKUP(D20,upahbahan,3,FALSE) -> 0 | J20: =G20*H20 -> 0
C21: 7 | D21: Air | F21: liter | G21: 17.415 | H21: =VLOOKUP(D21,upahbahan,3,FALSE) -> 200 | J21: =G21*H21 -> 3483
C22: 8 | D22: Residu | F22: liter | G22: 0.4 | H22: =VLOOKUP(D22,upahbahan,3,FALSE) -> 21000 | J22: =G22*H22 -> 8400
C23: JUMLAH HARGA BAHAN | J23: =SUM(J15:J22) -> 194361.89
C24: C | D24: PERALATAN
C25: JUMLAH HARGA ALAT | J25: 0
C26: D | D26: Jumlah (A+B+C) | J26: =J13+J23+J25 -> 316441.89
C27: E | D27: Biaya Umum dan Keuntungan 10%-15% x D | H27: =$Q$8 -> 0.1 | J27: =J26*H27 -> 31644.189
C28: F | D28: Harga Satuan Pekerjaan (D+E) | J28: =SUM(J26:J27) -> 348086.08
C30: 1.1.1.2 | D30: Pembuatan 1 m’ pagar sementara dari seng gelombang rangka kayu tinggi 2 meter | K30: =ROUNDDOWN(J52,-2) -> 245600
C31: No | D31: Uraian | F31: Sat. | G31: Koefisien | H31: Harga Satuan (Rp) | J31: Jumlah Harga (Rp)
C32: A | D32: TENAGA KERJA
C33: 1 | D33: Pekerja | E33: L.01 | F33: OH | G33: 0.25 | H33: =VLOOKUP(D33,upahbahan,3,FALSE) -> 100000 | J33: =G33*H33 -> 25000
C34: 2 | D34: Tukang kayu | E34: L.02 | F34: OH | G34: 0.125 | H34: =VLOOKUP(D34,upahbahan,3,FALSE) -> 135000 | J34: =G34*H34 -> 16875
C35: 3 | D35: Tukang batu | E35: L.02 | F35: OH | G35: 0.125 | H35: =VLOOKUP(D35,upahbahan,3,FALSE) -> 135000 | J35: =G35*H35 -> 16875
C36: 4 | D36: Kepala tukang | E36: L.03 | F36: OH | G36: 0.025 | H36: =VLOOKUP(D36,upahbahan,3,FALSE) -> 150000 | J36: =G36*H36 -> 3750
C37: 5 | D37: Mandor | E37: L.04 | F37: OH | G37: 0.008 | H37: =VLOOKUP(D37,upahbahan,3,FALSE) -> 160000 | J37: =G37*H37 -> 1280
C38: JUMLAH HARGA TENAGA KERJA | J38: =SUM(J33:J37) -> 63780
C39: B | D39: BAHAN
C40: 1 | D40: Kaso 5/7 kayu kelas II | F40: m3 | G40: 0.031 | H40: =VLOOKUP(D40,upahbahan,3,FALSE) -> 3015000 | J40: =G40*H40 -> 93465
C41: 2 | D41: Seng gelombang | F41: lembar | G41: 1.3125 | H41: =VLOOKUP(D41,upahbahan,3,FALSE) -> 0 | J41: =G41*H41 -> 0
C42: 3 | D42: Paku biasa 5 inchi | F42: kg | G42: 0.4271 | H42: =VLOOKUP(D42,upahbahan,3,FALSE) -> 20000 | J42: =G42*H42 -> 8542
...

Sheet Galian Tanah
C3: 1.2 | D3: PEKERJAAN GALIAN TANAH
C4: 1.2.1 | D4: Tanah Biasa
C5: 1.2.1.1 | D5: Cara Manual
C6: 1.2.1.1.1 | D6: Penggalian 1 m3 tanah biasa sedalam 0 s.d. 1 m untuk volume s.d. 200 m3 secara manual | J6: =ROUNDDOWN(I18,-2) -> 89100
C7: No | D7: Uraian | F7: Sat. | G7: Koefisien | H7: Harga Satuan (Rp) | I7: Jumlah Harga (Rp)
C8: A | D8: TENAGA KERJA
C9: 1 | D9: Pekerja | E9: L.01 | F9: OH | G9: 0.75 | H9: =VLOOKUP(D9,upahbahan,3,FALSE) -> 100000 | I9: =G9*H9 -> 75000
C10: 2 | D10: Mandor | E10: L.04 | F10: OH | G10: 0.038 | H10: =VLOOKUP(D10,upahbahan,3,FALSE) -> 160000 | I10: =G10*H10 -> 6080
C11: JUMLAH HARGA TENAGA KERJA | I11: =SUM(I9:I10) -> 81080
C12: B | D12: BAHAN
C13: JUMLAH HARGA BAHAN | I13: 0
C14: C | D14: PERALATAN
C15: JUMLAH HARGA ALAT | I15: 0
C16: D | D16: Jumlah (A+B+C) | I16: =I11+I13+I15 -> 81080
C17: E | D17: Biaya Umum dan Keuntungan 10%-15% x D | H17: 0.1 | I17: =I16*H17 -> 8108
C18: F | D18: Harga Satuan Pekerjaan (D+E) | I18: =SUM(I16:I17) -> 89188
C20: 1.2.1.1.2 | D20: Penggalian 1 m3 tanah biasa sedalam 0 s.d. 1 m untuk volume 200 m3 s.d 2.000 m3 secara manual | J20: =ROUNDDOWN(I32,-2) -> 71800
C21: No | D21: Uraian | F21: Sat. | G21: Koefisien | H21: Harga Satuan (Rp) | I21: Jumlah Harga (Rp)
C22: A | D22: TENAGA KERJA
C23: 1 | D23: Pekerja | E23: L.01 | F23: OH | G23: 0.563 | H23: =VLOOKUP(D23,upahbahan,3,FALSE) -> 100000 | I23: =G23*H23 -> 56300
C24: 2 | D24: Mandor | E24: L.04 | F24: OH | G24: 0.0563 | H24: =VLOOKUP(D24,upahbahan,3,FALSE) -> 160000 | I24: =G24*H24 -> 9008
C25: JUMLAH HARGA TENAGA KERJA | I25: =SUM(I23:I24) -> 65308
C26: B | D26: BAHAN
C27: JUMLAH HARGA BAHAN | I27: 0
C28: C | D28: PERALATAN
C29: JUMLAH HARGA ALAT | I29: 0
C30: D | D30: Jumlah (A+B+C) | I30: =I25+I27+I29 -> 65308
C31: E | D31: Biaya Umum dan Keuntungan 10%-15% x D | H31: 0.1 | I31: =I30*H31 -> 6530.8
C32: F | D32: Harga Satuan Pekerjaan (D+E) | I32: =SUM(I30:I31) -> 71838.8
C34: 1.2.1.1.3 | D34: Penggalian 1 m3 tanah biasa sedalam 0 s.d. 1 m untuk volume > 2.000 m3 secara Manual | J34: =ROUNDDOWN(I46,-2) -> 51000
C35: No | D35: Uraian | F35: Sat. | G35: Koefisien | H35: Harga Satuan (Rp) | I35: Jumlah Harga (Rp)
C36: A | D36: TENAGA KERJA
C37: 1 | D37: Pekerja | E37: L.01 | F37: OH | G37: 0.4 | H37: =VLOOKUP(D37,upahbahan,3,FALSE) -> 100000 | I37: =G37*H37 -> 40000
C38: 2 | D38: Mandor | E38: L.04 | F38: OH | G38: 0.04 | H38: =VLOOKUP(D38,upahbahan,3,FALSE) -> 160000 | I38: =G38*H38 -> 6400
C39: JUMLAH HARGA TENAGA KERJA | I39: =SUM(I37:I38) -> 46400
C40: B | D40: BAHAN
